Workbook
Name AllChecksPass: Checks!$F$14
Name OperatingAssets: DCF!$C$39
Name SharePrice: Inputs!$C$6
Name ValuePerShare: DCF!$C$49
Name WACC_Initial: WACC!$C$13

Sheet Cover
C3: Meta Platforms, Inc. (NASDAQ: META)
C5: Intrinsic Valuation: Damodaran FCFF (Ginzu) Framework
C7: Valuation date: 2 October 2026 | $ in millions except per share | For internal discussion
C10: Headline
C11: Intrinsic value per share | D11: =ValuePerShare -> 757.31576
C12: Share price | D12: =SharePrice -> 728.08
C13: Price as % of value | D13: =DCF!C51 -> 0.96139555
C14: Model checks | D14: =IF(AllChecksPass,"All checks pass","CHECK FAILURES - see Checks tab") -> All checks pass
C16: Contents
C17: Summary | D17: Key outputs, EV-to-equity bridge, scenarios, football field
C18: Inputs | D18: Every hard-coded input with its source (blue)
C19: Scenarios | D19: Scenario selector: the whole model runs on the active scenario
C20: Sensitivity | D20: Live data tables
C21: WACC | D21: Cost of capital (Damodaran's worksheet)
C22: DCF | D22: FCFF projection, terminal value, equity bridge
C23: Diagnostics | D23: Ginzu diagnostic questions vs industry
C24: Checks | D24: Tie-out to the engine and the Ginzu rules
C25: Sources | D25: Sources, methodology, disclaimer
C27: Colour convention
C28: Blue: hard-coded input
C29: Black: formula
C30: Green: link to another sheet
C31: Yellow fill: flex / selector cell (keep at base)
C33: Educational application of Damodaran's public framework and data; not investment advice.

Sheet Summary
B2: Valuation Summary: Meta Platforms, Inc. (NASDAQ: META)
B3: Intrinsic value, Damodaran FCFF (Ginzu) framework | Valuation date 2 October 2026 | $ in millions except per share
B5: Key outputs | F5: Enterprise value to equity bridge | T5: Chart data: football field
B6: Intrinsic value per share | C6: =ValuePerShare -> 757.31576 | F6: Value of operating assets | G6: =DCF!C39 -> 1921162.9 | T6: Reference | U6: Low | V6: High - low | W6: High
B7: Current share price | C7: =SharePrice -> 728.08 | F7: Less: debt | G7: =-DCF!C40 -> -112318 | T7: 52-week trading range | U7: =Inputs!$C$8 -> 520.26 | V7: =W7-U7 -> 259.56 | W7: =Inputs!$C$9 -> 779.82
B8: Upside / (downside) to value | C8: =DCF!C52 -> 0.040154601 | F8: Less: minority interests | G8: =-DCF!C41 -> 0 | T8: Analyst average target (third party) | U8: =Inputs!$C$10*0.995 -> 789.94045 | V8: =W8-U8 -> 7.9391 | W8: =Inputs!$C$10*1.005 -> 797.87955
B9: Price as % of value | C9: =DCF!C51 -> 0.96139555 | F9: Plus: cash | G9: =DCF!C42 -> 90260 | T9: DCF: cost of capital sensitivity | U9: =MIN(Sensitivity!C14:G22) -> 570.26716 | V9: =W9-U9 -> 499.2837 | W9: =MAX(Sensitivity!C14:G22) -> 1069.5509
B10: Market capitalization | C10: =SharePrice*Inputs!$C$7 -> 1854783.8 | F10: Less: tax on trapped cash | G10: =-DCF!C43 -> 0 | T10: DCF: growth x margin sensitivity | U10: =MIN(Sensitivity!C28:G34) -> 446.57702 | V10: =W10-U10 -> 912.67972 | W10: =MAX(Sensitivity!C28:G34) -> 1359.2567
B11: Intrinsic value of operating assets | C11: =OperatingAssets -> 1921162.9 | F11: Plus: non-operating assets | G11: =DCF!C44 -> 30157 | T11: DCF: scenario range | U11: =MIN(Scenarios!K8:K17) -> 588.69926 | V11: =W11-U11 -> 270.94937 | W11: =MAX(Scenarios!K8:K17) -> 859.64864
B12: Intrinsic value of equity | C12: =DCF!C46 -> 1929261.9 | F12: Plus: IPO proceeds retained | G12: =DCF!C45 -> 0 | T12: DCF base case | U12: =ValuePerShare*0.995 -> 753.52918 | V12: =W12-U12 -> 7.5731576 | W12: =ValuePerShare*1.005 -> 761.10234
B13: Initial / terminal cost of capital | C13: =TEXT(DCF!C27,"0.00%")&" / "&TEXT(DCF!C30,"0.00%") -> 8.51% / 9.48% | F13: Value of equity | G13: =DCF!C46 -> 1929261.9 | T13: Current share price | U13: =SharePrice*0.995 -> 724.4396 | V13: =W13-U13 -> 7.2808 | W13: =SharePrice*1.005 -> 731.7204
B14: Terminal growth | C14: =DCF!C31 -> 0.0528 | F14: Less: employee options | G14: =-DCF!C47 -> 0
B15: Year-10 revenue | C15: =DCF!M8 -> 647621.1 | F15: Shares outstanding | G15: =DCF!C48 -> 2547.5
B16: Breakeven target margin for value = price (engine) | C16: 0.38571536 | F16: Value per share | G16: =DCF!C49 -> 757.31576
B19: Scenario analysis (live; set the active scenario on the Scenarios tab)
B20: Scenario | C20: Value / share | D20: vs price
B21: =Scenarios!C8 -> Base case | C21: =Scenarios!K8 -> 757.31576 | D21: =C21/SharePrice-1 -> 0.040154601
B22: =Scenarios!C9 -> Sales-to-capital 1.5 in yrs 1-5 (Damodaran Feb-2024) | C22: =Scenarios!K9 -> 841.90509 | D22: =C22/SharePrice-1 -> 0.15633597
B23: =Scenarios!C10 -> Sales-to-capital 0.3 in yrs 1-5 (2026 capex pace) | C23: =Scenarios!K10 -> 672.72643 | D23: =C23/SharePrice-1 -> -0.076026768
B24: =Scenarios!C11 -> Growth yrs 2-5 at 8% (ad market slows) | C24: =Scenarios!K11 -> 661.03078 | D24: =C24/SharePrice-1 -> -0.092090463
B25: =Scenarios!C12 -> Growth yrs 2-5 at 15% (AI lifts ad pricing) | C25: =Scenarios!K12 -> 842.29277 | D25: =C25/SharePrice-1 -> 0.15686843
B26: =Scenarios!C13 -> Target margin 35% (AI depreciation and legal costs) | C26: =Scenarios!K13 -> 654.98289 | D26: =C26/SharePrice-1 -> -0.10039709
B27: =Scenarios!C14 -> Target margin 45% (AI pays off in efficiency) | C27: =Scenarios!K14 -> 859.64864 | D27: =C27/SharePrice-1 -> 0.18070629
B28: =Scenarios!C15 -> Terminal ROIC = cost of capital (Ginzu default) | C28: =Scenarios!K15 -> 588.69926 | D28: =C28/SharePrice-1 -> -0.19143602
B29: =Scenarios!C16 -> Next-year revenue = 4 x Q3 guidance midpoint ($250bn) | C29: =Scenarios!K16 -> 674.72861 | D29: =C29/SharePrice-1 -> -0.073276823
B30: =Scenarios!C17 -> 10% chance of failure (youth-harm litigation) | C30: =Scenarios!K17 -> 719.60893 | D30: =C30/SharePrice-1 -> -0.011634802

Sheet Inputs
B2: Inputs & Assumptions
B3: $ in millions except per share | Blue = hard-coded input (source in column N) | Column D = live value of the active scenario
C4: Base | D4: Live
B5: Market data
B6: Share price | C6: 728.08 | N6: MARKET: META close 2026-10-02, $728.08 (https://stockanalysis.com/stocks/meta/)
B7: Shares outstanding | C7: 2547.5 | N7: FILING: 10-Q cover, 2026-07-24: Class A 2,205,128,509 + Class B 342,377,716 = 2,547.5 million
B8: 52-week low | C8: 520.26 | N8: Market data (third party)
B9: 52-week high | C9: 779.82 | N9: Market data (third party)
B10: Analyst average price target (third party) | C10: 793.91 | N10: Market data (third party)
B12: Base year (trailing twelve months)
B13: Revenues (base year) | C13: 228247 | N13: FILING: TTM to 2026-06-30 = FY2025 200,966 + H1 2026 117,111 - H1 2025 89,830 (10-K 2025; 10-Q 2026-06-30), https://www.sec.gov/Archives/edgar/data/1326801/000162828026050705/meta-20260630.htm
B14: Operating income (EBIT, base year) | C14: 86926 | N14: FILING: TTM income from operations = 83,276 + 41,647 - 37,997 (includes $2.4bn of Q2-2026 legal charges)
B15: Book value of equity | C15: 261221 | N15: FILING: total stockholders' equity 261,221 at 2026-06-30
B16: Book value of debt (incl. leases) | C16: 112318 | N16: FILING: long-term debt 83,664 + operating lease liabilities 2,425 + 26,229 = 112,318 at 2026-06-30 (finance lease liabilities sit in other liabilities and are not added)
B17: Cash & marketable securities | C17: 90260 | N17: FILING: cash and cash equivalents 15,462 + marketable securities 74,798 at 2026-06-30 (restricted cash excluded)
B18: Non-operating assets (cross holdings) | C18: 30157 | N18: FILING: non-marketable equity investments 30,157 at 2026-06-30 (cross holdings)
B19: Minority interests | C19: 0 | N19: FILING: none
B20: Revenues, prior year | C20: 178804 | N20: FILING: TTM to 2025-06-30 = 164,501 + 89,830 - 75,527
B21: Net operating loss carried forward | C21: 0 | N21: Ginzu default (none)
B22: IPO proceeds retained by the firm | C22: 0 | N22: None
B23: New IPO shares issued at estimated value (1 = yes) | C23: 0 | N23: No
B25: Value drivers (the story)
B26: Revenue growth, next year | C26: 0.23 | D26: =INDEX(Scenarios!$H$8:$H$17,Scenarios!$D$5) -> 0.23 | N26: JUDGMENT anchored on consensus: next-12-month revenue ~$281bn = consensus 2026 $254.2bn less actual H1 $117.1bn, plus ~47% of consensus 2027 $306.4bn (S&P Global via StockAnalysis, 2026-10-02); company guides Q3-2026 revenue to $61-64bn (8-K 2026-07-29)
B27: Revenue growth, years 2-5 (CAGR) | C27: 0.12 | D27: =INDEX(Scenarios!$E$8:$E$17,Scenarios!$D$5) -> 0.12 | N27: DAMODARAN Feb-2024 Meta story: 12% a year (Seven Samurai post). Breakeven vs price: 10.9%
B28: Operating margin, next year | C28: 0.46 | N28: JUDGMENT: 2026 expense guidance ($165-169bn) against ~$254bn of revenue is a ~34% GAAP margin; capitalizing R&D adds ~12 points (current R&D-adjusted margin 49.1%)
B29: Target pre-tax operating margin | C29: 0.4 | D29: =INDEX(Scenarios!$F$8:$F$17,Scenarios!$D$5) -> 0.4 | N29: DAMODARAN Feb-2024 Meta story: 40% target operating margin by year 5
B30: Year of margin convergence | C30: 5 | N30: DAMODARAN Meta2024 input (year 5)
B31: Sales to capital, years 1-5 | C31: 0.5 | D31: =INDEX(Scenarios!$D$8:$D$17,Scenarios!$D$5) -> 0.5 | N31: JUDGMENT anchored on filings: TTM reinvestment ~$94.8bn (capex 89,325 + finance-lease principal 3,104 - depreciation 22,729 + net R&D capitalization 25,058) bought $49.4bn of extra revenue = 0.52; current revenue / invested capital 0.56; 2026 capex guided to $130-145bn. Damodaran's Feb-2024 input was 1.5
B32: Sales to capital, years 6-10 | C32: 1.5 | N32: DAMODARAN Meta2024 input (1.5): efficiency returns once the AI build-out matures
B34: Rates, terminal value and default-assumption overrides
B35: Effective tax rate | C35: 0.16 | N35: FILING/GUIDANCE: 16%, the midpoint of the company's 15-17% outlook for the rest of 2026 (Q2-2026 rate 15.5%); the TTM rate is distorted by a $15.93bn Q3-2025 charge and an $8.03bn Q1-2026 benefit
B36: Marginal tax rate | C36: 0.25 | N36: DAMODARAN Meta2024 input (25%)
B37: Keep effective tax rate forever (1 = yes) | C37: 0 | N37: Ginzu default (tax drifts to marginal)
B38: Riskfree rate | C38: 0.0528 | N38: MARKET: US 10-year Treasury par yield 5.28% on 2026-10-02 (home.treasury.gov daily yield curve)
B39: Mature market equity risk premium | C39: 0.042 | N39: DAMODARAN July 2026 country-risk update: mature market ERP 4.20% (country_risk.py, ctrypremJuly26.xlsx)
B40: Terminal return on capital (override) | C40: 0.15 | D40: =INDEX(Scenarios!$G$8:$G$17,Scenarios!$D$5) -> 0.15 | N40: DAMODARAN Meta2024 override (15%: lasting advantages of the ad platforms)
B41: Reinvestment lag (years, 0-3) | C41: 1 | N41: Ginzu default (1 year)
B42: Probability of failure | C42: 0 | D42: =INDEX(Scenarios!$I$8:$I$17,Scenarios!$D$5) -> 0 | N42: Ginzu default (no failure)
B43: Failure proceeds tied to ("B" book / "V" fair value) | C43: V | N43: Ginzu default
B44: Failure proceeds, % of that basis | C44: 0 | D44: =INDEX(Scenarios!$J$8:$J$17,Scenarios!$D$5) -> 0 | N44: Ginzu default
...

Sheet Scenarios
B2: Scenario Analysis
B3: Set the active scenario in D5: the whole model runs on it (Inputs column D). The value column is a live data table over all scenarios.
C5: Active scenario (1-10) | D5: 1 | E5: =INDEX($C$8:$C$17,$D$5) -> Base case
N6: Data table (What-If; do not edit)
B7: # | C7: Scenario | D7: Sales to capital, years 1-5 | E7: Revenue growth, years 2-5 (CAGR) | F7: Target pre-tax operating margin | G7: Terminal return on capital (override) | H7: Revenue growth, next year | I7: Probability of failure | J7: Failure proceeds, % of that basis | K7: Value / share | L7: vs price | O7: =ValuePerShare -> 757.31576
B8: 1 | C8: Base case | D8: =Inputs!$C$31 -> 0.5 | E8: =Inputs!$C$27 -> 0.12 | F8: =Inputs!$C$29 -> 0.4 | G8: =Inputs!$C$40 -> 0.15 | H8: =Inputs!$C$26 -> 0.23 | I8: =Inputs!$C$42 -> 0 | J8: =Inputs!$C$44 -> 0 | K8: =O8 -> 757.31576 | L8: =K8/SharePrice-1 -> 0.040154601 | N8: 1 | O8: 757.31576
B9: 2 | C9: Sales-to-capital 1.5 in yrs 1-5 (Damodaran Feb-2024) | D9: 1.5 | E9: =E$8 -> 0.12 | F9: =F$8 -> 0.4 | G9: =G$8 -> 0.15 | H9: =H$8 -> 0.23 | I9: =I$8 -> 0 | J9: =J$8 -> 0 | K9: =O9 -> 841.90509 | L9: =K9/SharePrice-1 -> 0.15633597 | N9: 2 | O9: 841.90509
B10: 3 | C10: Sales-to-capital 0.3 in yrs 1-5 (2026 capex pace) | D10: 0.3 | E10: =E$8 -> 0.12 | F10: =F$8 -> 0.4 | G10: =G$8 -> 0.15 | H10: =H$8 -> 0.23 | I10: =I$8 -> 0 | J10: =J$8 -> 0 | K10: =O10 -> 672.72643 | L10: =K10/SharePrice-1 -> -0.076026768 | N10: 3 | O10: 672.72643
B11: 4 | C11: Growth yrs 2-5 at 8% (ad market slows) | D11: =D$8 -> 0.5 | E11: 0.08 | F11: =F$8 -> 0.4 | G11: =G$8 -> 0.15 | H11: =H$8 -> 0.23 | I11: =I$8 -> 0 | J11: =J$8 -> 0 | K11: =O11 -> 661.03078 | L11: =K11/SharePrice-1 -> -0.092090463 | N11: 4 | O11: 661.03078
B12: 5 | C12: Growth yrs 2-5 at 15% (AI lifts ad pricing) | D12: =D$8 -> 0.5 | E12: 0.15 | F12: =F$8 -> 0.4 | G12: =G$8 -> 0.15 | H12: =H$8 -> 0.23 | I12: =I$8 -> 0 | J12: =J$8 -> 0 | K12: =O12 -> 842.29277 | L12: =K12/SharePrice-1 -> 0.15686843 | N12: 5 | O12: 842.29277
B13: 6 | C13: Target margin 35% (AI depreciation and legal costs) | D13: =D$8 -> 0.5 | E13: =E$8 -> 0.12 | F13: 0.35 | G13: =G$8 -> 0.15 | H13: =H$8 -> 0.23 | I13: =I$8 -> 0 | J13: =J$8 -> 0 | K13: =O13 -> 654.98289 | L13: =K13/SharePrice-1 -> -0.10039709 | N13: 6 | O13: 654.98289
B14: 7 | C14: Target margin 45% (AI pays off in efficiency) | D14: =D$8 -> 0.5 | E14: =E$8 -> 0.12 | F14: 0.45 | G14: =G$8 -> 0.15 | H14: =H$8 -> 0.23 | I14: =I$8 -> 0 | J14: =J$8 -> 0 | K14: =O14 -> 859.64864 | L14: =K14/SharePrice-1 -> 0.18070629 | N14: 7 | O14: 859.64864
B15: 8 | C15: Terminal ROIC = cost of capital (Ginzu default) | D15: =D$8 -> 0.5 | E15: =E$8 -> 0.12 | F15: =F$8 -> 0.4 | G15: 0.0948 | H15: =H$8 -> 0.23 | I15: =I$8 -> 0 | J15: =J$8 -> 0 | K15: =O15 -> 588.69926 | L15: =K15/SharePrice-1 -> -0.19143602 | N15: 8 | O15: 588.69926
B16: 9 | C16: Next-year revenue = 4 x Q3 guidance midpoint ($250bn) | D16: =D$8 -> 0.5 | E16: =E$8 -> 0.12 | F16: =F$8 -> 0.4 | G16: =G$8 -> 0.15 | H16: 0.0953 | I16: =I$8 -> 0 | J16: =J$8 -> 0 | K16: =O16 -> 674.72861 | L16: =K16/SharePrice-1 -> -0.073276823 | N16: 9 | O16: 674.72861
B17: 10 | C17: 10% chance of failure (youth-harm litigation) | D17: =D$8 -> 0.5 | E17: =E$8 -> 0.12 | F17: =F$8 -> 0.4 | G17: =G$8 -> 0.15 | H17: =H$8 -> 0.23 | I17: 0.1 | J17: 0.5 | K17: =O17 -> 719.60893 | L17: =K17/SharePrice-1 -> -0.011634802 | N17: 10 | O17: 719.60893

Sheet Sensitivity
B2: Sensitivity Analysis
B3: Live Excel data tables on value per share. Flex cells (yellow) must stay neutral for the base case; the data tables vary them.
B4: Flex cells (neutral values = base case)
B5: Change in initial cost of capital | C5: 0
B6: Change in terminal cost of capital | C6: 0
B7: Change in revenue growth, years 1-5 | C7: 0
B8: Change in target operating margin | C8: 0
B9: Change in riskfree rate | C9: 0
B11: Value per share: initial vs terminal cost of capital (change from base)
B12: Rows: change in initial cost of capital | Columns: change in terminal cost of capital
B13: =ValuePerShare -> 757.31576 | C13: -0.01 | D13: -0.005 | E13: 0 | F13: 0.005 | G13: 0.01 | I13: Shaded green: value at or above the current share price
B14: -0.02 | C14: 1069.5509 | D14: 947.96128 | E14: 855.21276 | F14: 782.10223 | G14: 722.96625 | I14: Current share price
B15: -0.015 | C15: 1036.8248 | D15: 919.16288 | E15: 829.41037 | F15: 758.66145 | G15: 701.43564 | I15: =SharePrice -> 728.08
B16: -0.01 | C16: 1005.2587 | D16: 891.38214 | E16: 804.51707 | F16: 736.0442 | G16: 680.65935
B17: -0.005 | C17: 974.80654 | D17: 864.5788 | E17: 780.49698 | F17: 714.21802 | G17: 660.6077
B18: 0 | C18: 945.42446 | D18: 838.71436 | E18: 757.31576 | F18: 693.15186 | G18: 641.25229
B19: 0.005 | C19: 917.07035 | D19: 813.75198 | E19: 734.94056 | F19: 672.81602 | G19: 622.56597
B20: 0.01 | C20: 889.70398 | D20: 789.65642 | E20: 713.33996 | F20: 653.18207 | G20: 604.52275
B21: 0.015 | C21: 863.28685 | D21: 766.39397 | E21: 692.48387 | F21: 634.22283 | G21: 587.09775
B22: 0.02 | C22: 837.78211 | D22: 743.93236 | E22: 672.34353 | F22: 615.91224 | G22: 570.26716
B25: Value per share: revenue growth vs operating margin (change from base)
B26: Rows: change in revenue growth, years 1-5 | Columns: change in target operating margin
B27: =ValuePerShare -> 757.31576 | C27: -0.05 | D27: -0.025 | E27: 0 | F27: 0.025 | G27: 0.05
B28: -0.1 | C28: 446.57702 | D28: 474.79569 | E28: 503.01437 | F28: 531.23304 | G28: 559.45171
B29: -0.05 | C29: 537.46346 | D29: 575.63842 | E29: 613.81338 | F29: 651.98835 | G29: 690.16331
B30: -0.025 | C30: 592.46754 | D30: 636.71381 | E30: 680.96009 | F30: 725.20636 | G30: 769.45263
B31: 0 | C31: 654.98289 | D31: 706.14932 | E31: 757.31576 | F31: 808.4822 | G31: 859.64864
B32: 0.025 | C32: 725.97965 | D32: 785.01666 | E32: 844.05367 | F32: 903.09067 | G32: 962.12768
B33: 0.05 | C33: 806.53148 | D33: 874.5011 | E33: 942.47072 | F33: 1010.4403 | G33: 1078.41
B34: 0.1 | C34: 1001.1652 | D34: 1090.6881 | E34: 1180.211 | F34: 1269.7339 | G34: 1359.2567
B37: Riskfree rate: value per share and cost of capital
B38: Change in riskfree rate | C38: Value / share | D38: Initial WACC
C39: =ValuePerShare -> 757.31576 | D39: =WACC_Initial -> 0.085061237
B40: -0.015 | C40: 915.44624 | D40: 0.070061237
B41: -0.01 | C41: 860.3116 | D41: 0.075061237
B42: -0.005 | C42: 807.63817 | D42: 0.080061237
B43: 0 | C43: 757.31576 | D43: 0.085061237
B44: 0.005 | C44: 709.23941 | D44: 0.090061237
B45: 0.01 | C45: 663.30911 | D45: 0.095061237
B46: 0.015 | C46: 619.42957 | D46: 0.10006124

Sheet WACC
B2: Cost of Capital
B3: Damodaran's cost-of-capital worksheet, approach: industry_average. Data: Damodaran (Updated January 1, 2026).
B5: Riskfree rate (live, incl. flex) | C5: =Inputs!$C$38+Sensitivity!$C$9 -> 0.0528
B6: Marginal tax rate | C6: =Inputs!$C$36 -> 0.25
B8: Industry-average cost of capital (US)
B9: Industry cost of capital: Advertising (US) | C9: 0.078061237 | J9: Damodaran US industry averages (Updated January 1, 2026)
B11: Riskfree rate in the industry data | C11: 0.0458 | J11: Damodaran data
B12: Riskfree adjustment (live riskfree - data riskfree) | C12: =$C$5-C11 -> 0.007
B13: Cost of capital (initial) | C13: =C9+C12 -> 0.085061237

Sheet DCF
B2: Discounted Cash Flow (FCFF)
B3: Damodaran fcffsimpleginzu mechanics: tax drifts to marginal in years 6-10, NOL shield, cost of capital drifts to terminal, terminal reinvestment = g / ROIC. $ in millions except per share.
C4: Base year | D4: Year 1 | E4: Year 2 | F4: Year 3 | G4: Year 4 | H4: Year 5 | I4: Year 6 | J4: Year 7 | K4: Year 8 | L4: Year 9 | M4: Year 10 | N4: Terminal
B5: Year (t) | C5: 0 | D5: 1 | E5: 2 | F5: 3 | G5: 4 | H5: 5 | I5: 6 | J5: 7 | K5: 8 | L5: 9 | M5: 10 | N5: 11
B7: Revenue growth | D7: =Inputs!$D$26+Sensitivity!$C$7 -> 0.23 | E7: =Inputs!$D$27+Sensitivity!$C$7 -> 0.12 | F7: =Inputs!$D$27+Sensitivity!$C$7 -> 0.12 | G7: =Inputs!$D$27+Sensitivity!$C$7 -> 0.12 | H7: =Inputs!$D$27+Sensitivity!$C$7 -> 0.12 | I7: =$H$7-($H$7-$C$31)/5*1 -> 0.10656 | J7: =$H$7-($H$7-$C$31)/5*2 -> 0.09312 | K7: =$H$7-($H$7-$C$31)/5*3 -> 0.07968 | L7: =$H$7-($H$7-$C$31)/5*4 -> 0.06624 | M7: =$H$7-($H$7-$C$31)/5*5 -> 0.0528 | N7: =$C$31 -> 0.0528
B8: Revenue | C8: =Inputs!$C$13 -> 228247 | D8: =C8*(1+D7) -> 280743.81 | E8: =D8*(1+E7) -> 314433.07 | F8: =E8*(1+F7) -> 352165.04 | G8: =F8*(1+G7) -> 394424.84 | H8: =G8*(1+H7) -> 441755.82 | I8: =H8*(1+I7) -> 488829.32 | J8: =I8*(1+J7) -> 534349.11 | K8: =J8*(1+K7) -> 576926.04 | ... N8: =M8*(1+N7) -> 681815.5
B9: Operating margin | C9: =C10/C8 -> 0.49062638 | D9: =Inputs!$C$28 -> 0.46 | E9: =IF(E$5>Inputs!$C$30,(Inputs!$D$29+Sensitivity!$C$8),(Inputs!$D$29+Sensitivity!$C$8)-((Inputs!$D$29+Sensitivity!$C$8)-$D$9)/Inputs!$C$30*(Inputs!$C$30-E$5)) -> 0.436 | F9: =IF(F$5>Inputs!$C$30,(Inputs!$D$29+Sensitivity!$C$8),(Inputs!$D$29+Sensitivity!$C$8)-((Inputs!$D$29+Sensitivity!$C$8)-$D$9)/Inputs!$C$30*(Inputs!$C$30-F$5)) -> 0.424 | G9: =IF(G$5>Inputs!$C$30,(Inputs!$D$29+Sensitivity!$C$8),(Inputs!$D$29+Sensitivity!$C$8)-((Inputs!$D$29+Sensitivity!$C$8)-$D$9)/Inputs!$C$30*(Inputs!$C$30-G$5)) -> 0.412 | H9: =IF(H$5>Inputs!$C$30,(Inputs!$D$29+Sensitivity!$C$8),(Inputs!$D$29+Sensitivity!$C$8)-((Inputs!$D$29+Sensitivity!$C$8)-$D$9)/Inputs!$C$30*(Inputs!$C$30-H$5)) -> 0.4 | I9: =IF(I$5>Inputs!$C$30,(Inputs!$D$29+Sensitivity!$C$8),(Inputs!$D$29+Sensitivity!$C$8)-((Inputs!$D$29+Sensitivity!$C$8)-$D$9)/Inputs!$C$30*(Inputs!$C$30-I$5)) -> 0.4 | J9: =IF(J$5>Inputs!$C$30,(Inputs!$D$29+Sensitivity!$C$8),(Inputs!$D$29+Sensitivity!$C$8)-((Inputs!$D$29+Sensitivity!$C$8)-$D$9)/Inputs!$C$30*(Inputs!$C$30-J$5)) -> 0.4 | K9: =IF(K$5>Inputs!$C$30,(Inputs!$D$29+Sensitivity!$C$8),(Inputs!$D$29+Sensitivity!$C$8)-((Inputs!$D$29+Sensitivity!$C$8)-$D$9)/Inputs!$C$30*(Inputs!$C$30-K$5)) -> 0.4 | L9: =IF(L$5>Inputs!$C$30,(Inputs!$D$29+Sensitivity!$C$8),(Inputs!$D$29+Sensitivity!$C$8)-((Inputs!$D$29+Sensitivity!$C$8)-$D$9)/Inputs!$C$30*(Inputs!$C$30-L$5)) -> 0.4 | M9: =IF(M$5>Inputs!$C$30,(Inputs!$D$29+Sensitivity!$C$8),(Inputs!$D$29+Sensitivity!$C$8)-((Inputs!$D$29+Sensitivity!$C$8)-$D$9)/Inputs!$C$30*(Inputs!$C$30-M$5)) -> 0.4 | N9: =M9 -> 0.4
B10: Operating income (EBIT) | C10: =Inputs!$C$14+C57 -> 111984 | D10: =D9*D8 -> 129142.15 | E10: =E9*E8 -> 137092.82 | F10: =F9*F8 -> 149317.97 | G10: =G9*G8 -> 162503.03 | H10: =H9*H8 -> 176702.33 | I10: =I9*I8 -> 195531.73 | J10: =J9*J8 -> 213739.64 | K10: =K9*K8 -> 230770.42 | ... N10: =N9*N8 -> 272726.2
B11: Tax rate | C11: =Inputs!$C$35 -> 0.16 | D11: =C11 -> 0.16 | E11: =D11 -> 0.16 | F11: =E11 -> 0.16 | G11: =F11 -> 0.16 | H11: =G11 -> 0.16 | I11: =H11+(IF(Inputs!$C$37=1,Inputs!$C$35,Inputs!$C$36)-$H$11)/5 -> 0.178 | J11: =I11+(IF(Inputs!$C$37=1,Inputs!$C$35,Inputs!$C$36)-$H$11)/5 -> 0.196 | K11: =J11+(IF(Inputs!$C$37=1,Inputs!$C$35,Inputs!$C$36)-$H$11)/5 -> 0.214 | L11: =K11+(IF(Inputs!$C$37=1,Inputs!$C$35,Inputs!$C$36)-$H$11)/5 -> 0.232 | M11: =L11+(IF(Inputs!$C$37=1,Inputs!$C$35,Inputs!$C$36)-$H$11)/5 -> 0.25 | N11: =IF(Inputs!$C$37=1,Inputs!$C$35,Inputs!$C$36) -> 0.25
B12: Net operating loss carried forward | C12: =Inputs!$C$21 -> 0 | D12: =IF(D10<0,C12-D10,IF(C12>D10,C12-D10,0)) -> 0 | E12: =IF(E10<0,D12-E10,IF(D12>E10,D12-E10,0)) -> 0 | F12: =IF(F10<0,E12-F10,IF(E12>F10,E12-F10,0)) -> 0 | G12: =IF(G10<0,F12-G10,IF(F12>G10,F12-G10,0)) -> 0 | H12: =IF(H10<0,G12-H10,IF(G12>H10,G12-H10,0)) -> 0 | I12: =IF(I10<0,H12-I10,IF(H12>I10,H12-I10,0)) -> 0 | J12: =IF(J10<0,I12-J10,IF(I12>J10,I12-J10,0)) -> 0 | K12: =IF(K10<0,J12-K10,IF(J12>K10,J12-K10,0)) -> 0 | ... M12: =IF(M10<0,L12-M10,IF(L12>M10,L12-M10,0)) -> 0
B13: After-tax operating income | C13: =IF(C10>0,C10*(1-C11),C10) -> 94066.56 | D13: =IF(D10>0,IF(D10<C12,D10,D10-(D10-C12)*D11),D10) -> 108479.41 | E13: =IF(E10>0,IF(E10<D12,E10,E10-(E10-D12)*E11),E10) -> 115157.97 | F13: =IF(F10>0,IF(F10<E12,F10,F10-(F10-E12)*F11),F10) -> 125427.1 | G13: =IF(G10>0,IF(G10<F12,G10,G10-(G10-F12)*G11),G10) -> 136502.55 | H13: =IF(H10>0,IF(H10<G12,H10,H10-(H10-G12)*H11),H10) -> 148429.96 | I13: =IF(I10>0,IF(I10<H12,I10,I10-(I10-H12)*I11),I10) -> 160727.08 | J13: =IF(J10>0,IF(J10<I12,J10,J10-(J10-I12)*J11),J10) -> 171846.67 | K13: =IF(K10>0,IF(K10<J12,K10,K10-(K10-J12)*K11),K10) -> 181385.55 | ... M13: =IF(M10>0,IF(M10<L12,M10,M10-(M10-L12)*M11),M10) -> 194286.33 | N13: =N10*(1-N11) -> 204544.65
B14: Sales to capital | D14: =Inputs!$D$31 -> 0.5 | E14: =Inputs!$D$31 -> 0.5 | F14: =Inputs!$D$31 -> 0.5 | G14: =Inputs!$D$31 -> 0.5 | H14: =Inputs!$D$31 -> 0.5 | I14: =Inputs!$C$32 -> 1.5 | J14: =Inputs!$C$32 -> 1.5 | K14: =Inputs!$C$32 -> 1.5 | L14: =Inputs!$C$32 -> 1.5 | M14: =Inputs!$C$32 -> 1.5
B15: Less: reinvestment | D15: =CHOOSE(Inputs!$C$41+1,(D8-C8)/D14,(E8-D8)/D14,(F8-E8)/D14,(G8-F8)/D14) -> 67378.514 | E15: =CHOOSE(Inputs!$C$41+1,(E8-D8)/E14,(F8-E8)/E14,(G8-F8)/E14,(H8-G8)/E14) -> 75463.936 | F15: =CHOOSE(Inputs!$C$41+1,(F8-E8)/F14,(G8-F8)/F14,(H8-G8)/F14,(I8-H8)/F14) -> 84519.608 | G15: =CHOOSE(Inputs!$C$41+1,(G8-F8)/G14,(H8-G8)/G14,(I8-H8)/G14,(J8-I8)/G14) -> 94661.961 | H15: =CHOOSE(Inputs!$C$41+1,(H8-G8)/H14,(I8-H8)/H14,(J8-I8)/H14,(K8-J8)/H14) -> 94147 | I15: =CHOOSE(Inputs!$C$41+1,(I8-H8)/I14,(J8-I8)/I14,(K8-J8)/I14,(L8-K8)/I14) -> 30346.524 | J15: =CHOOSE(Inputs!$C$41+1,(J8-I8)/J14,(K8-J8)/J14,(L8-K8)/J14,(M8-L8)/J14) -> 28384.625 | K15: =CHOOSE(Inputs!$C$41+1,(K8-J8)/K14,(L8-K8)/K14,(M8-L8)/K14,(N8-M8)/K14) -> 25477.054 | L15: =CHOOSE(Inputs!$C$41+1,(L8-K8)/L14,(M8-L8)/L14,(N8-M8)/L14,$N$8*$N$7/L14) -> 21652.985 | M15: =CHOOSE(Inputs!$C$41+1,(M8-L8)/M14,(N8-M8)/M14,$N$8*$N$7/M14,L15*(1+$C$31)) -> 22796.263 | N15: =IF($C$31>0,$C$31/$C$32*N13,0) -> 71999.716
B16: Free cash flow to firm (FCFF) | D16: =D13-D15 -> 41100.894 | E16: =E13-E15 -> 39694.03 | F16: =F13-F15 -> 40907.49 | G16: =G13-G15 -> 41840.587 | H16: =H13-H15 -> 54282.955 | I16: =I13-I15 -> 130380.56 | J16: =J13-J15 -> 143462.05 | K16: =K13-K15 -> 155908.49 | ... N16: =N13-N15 -> 132544.93
B18: Cost of capital | D18: =$C$27 -> 0.085061237 | E18: =$C$27 -> 0.085061237 | F18: =$C$27 -> 0.085061237 | G18: =$C$27 -> 0.085061237 | H18: =$C$27 -> 0.085061237 | I18: =H18-($H$18-$C$30)/5 -> 0.08700899 | J18: =I18-($H$18-$C$30)/5 -> 0.088956742 | K18: =J18-($H$18-$C$30)/5 -> 0.090904495 | L18: =K18-($H$18-$C$30)/5 -> 0.092852247 | M18: =L18-($H$18-$C$30)/5 -> 0.0948 | N18: =$C$30 -> 0.0948
B19: Cumulative discount factor | D19: =1/(1+D18) -> 0.92160697 | E19: =D19/(1+E18) -> 0.84935941 | F19: =E19/(1+F18) -> 0.78277555 | G19: =F19/(1+G18) -> 0.7214114 | H19: =G19/(1+H18) -> 0.66485778 | I19: =H19/(1+I18) -> 0.61163963 | J19: =I19/(1+J18) -> 0.56167487 | K19: =J19/(1+K18) -> 0.5148708 | L19: =K19/(1+L18) -> 0.47112572 | M19: =L19/(1+M18) -> 0.43033039
B20: Present value of FCFF | D20: =D16*D19 -> 37878.87 | E20: =E16*E19 -> 33714.498 | F20: =F16*F19 -> 32021.383 | G20: =G16*G19 -> 30184.277 | H20: =H16*H19 -> 36090.445 | I20: =I16*I19 -> 79745.916 | J20: =J16*J19 -> 80579.027 | K20: =K16*K19 -> 80272.731 | ... M20: =M16*M19 -> 73797.388
B22: Invested capital | C22: =Inputs!$C$15+Inputs!$C$16-Inputs!$C$17+C55 -> 407785.33 | D22: =C22+D15 -> 475163.85 | E22: =D22+E15 -> 550627.78 | F22: =E22+F15 -> 635147.39 | G22: =F22+G15 -> 729809.35 | H22: =G22+H15 -> 823956.35 | I22: =H22+I15 -> 854302.88 | J22: =I22+J15 -> 882687.5 | K22: =J22+K15 -> 908164.56 | ... M22: =L22+M15 -> 952613.81
B23: Return on invested capital | C23: =C13/C22 -> 0.23067666 | D23: =D13/C22 -> 0.26602087 | E23: =E13/D22 -> 0.24235423 | F23: =F13/E22 -> 0.22778927 | G23: =G13/F22 -> 0.21491476 | H23: =H13/G22 -> 0.20338182 | I23: =I13/H22 -> 0.19506747 | J23: =J13/I22 -> 0.20115427 | K23: =K13/J22 -> 0.20549237 | ... M23: =M13/L22 -> 0.20895103 | N23: =$C$32 -> 0.15
B25: Valuation
B26: Initial cost of capital (WACC tab) | C26: =WACC!$C$13 -> 0.085061237
B27: Initial cost of capital (incl. flex) | C27: =C26+Sensitivity!$C$5 -> 0.085061237
B28: Riskfree rate after year 10 | C28: =WACC!$C$5 -> 0.0528
B29: Mature market ERP | C29: =Inputs!$C$39 -> 0.042
B30: Terminal cost of capital | C30: =C28+C29+Sensitivity!$C$6 -> 0.0948
B31: Terminal growth rate | C31: =C28 -> 0.0528
B32: Terminal return on capital | C32: =Inputs!$D$40 -> 0.15
B33: Terminal value = FCFF(t+1) / (r - g) | C33: =N16/(C30-C31) -> 3155831.7
B34: PV of terminal value | C34: =C33*M19 -> 1358050.3
B35: PV of FCFF, years 1-10 | C35: =SUM(D20:M20) -> 563112.59
B36: Sum of present values | C36: =C34+C35 -> 1921162.9
B37: Probability of failure | C37: =Inputs!$D$42 -> 0
B38: Proceeds if the firm fails | C38: =IF(EXACT(Inputs!$C$43,"B"),Inputs!$C$15+Inputs!$C$16,C36)*Inputs!$D$44 -> 0
B39: Value of operating assets | C39: =C36*(1-C37)+C38*C37 -> 1921162.9
B40: Less: debt | C40: =Inputs!$C$16 -> 112318
B41: Less: minority interests | C41: =Inputs!$C$19 -> 0
B42: Plus: cash | C42: =Inputs!$C$17 -> 90260
B43: Less: tax on repatriating trapped cash | C43: 0
B44: Plus: non-operating assets | C44: =Inputs!$C$18 -> 30157
B45: Plus: IPO proceeds retained | C45: =Inputs!$C$22 -> 0
...

Sheet Diagnostics
B2: Diagnostics
B3: The Ginzu 'Diagnostics' sheet: the forecast next to industry averages, with the questions Damodaran suggests asking
B5: 1. Revenue growth
C6: Industry (5-yr avg) | D6: Last year | E6: Next year | F6: CAGR yrs 2-5 | H6: Growth above industry: is the company small? Very different from last year's growth: why?
C7: =Inputs!$C$54 -> 0.17674522 | D7: =DCF!C8/Inputs!$C$20-1 -> 0.27652066 | E7: =DCF!D7 -> 0.23 | F7: =(DCF!H8/DCF!D8)^(1/4)-1 -> 0.12
B9: 2. Dollar revenues
C10: Now | D10: Year 1 | E10: Year 5 | F10: Year 10 | H10: How big is the total market, what do its biggest firms earn, what share does year 10 imply?
C11: =DCF!C8 -> 228247 | D11: =DCF!D8 -> 280743.81 | E11: =DCF!H8 -> 441755.82 | F11: =DCF!M8 -> 647621.1
B13: 3. Operating margin
C14: Industry | D14: Now | E14: Year 5 | F14: Year 10 | H14: Industry margins? Unit economics (the cost of the extra unit)? What does competition look like?
C15: =Inputs!$C$55 -> 0.10190391 | D15: =DCF!C9 -> 0.49062638 | E15: =DCF!H9 -> 0.4 | F15: =DCF!M9 -> 0.4
B17: 4. Reinvestment & ROIC
C18: Industry sales/capital | D18: Sales/capital now | E18: ROIC year 10 | F18: Stable ROIC | H18: Bounce-back or new growth? Excess capacity? Does efficiency change with scale? Comfortable with year-10 ROIC?
C19: =Inputs!$C$56 -> 3.8532841 | D19: =DCF!C8/DCF!C22 -> 0.55972342 | E19: =DCF!M23 -> 0.20895103 | F19: =DCF!N23 -> 0.15
B21: 5. Cost of capital
C22: Industry | D22: Years 1-5 | E22: Compounded | F22: Stable | H22: How does it compare with the industry? Why does it change over time? Is the failure rate consistent with the company?
C23: =Inputs!$C$57 -> 0.078061237 | D23: =DCF!D18 -> 0.085061237 | E23: =(1/DCF!M19)^(1/10)-1 -> 0.087977209 | F23: =DCF!N18 -> 0.0948
B25: 6. Value vs price
C26: Value / price | D26: Flag | H26: Ginzu flags: value below 50% or above 200% of price -> revisit growth, target margin, sales/capital and terminal ROIC.
C27: =DCF!C49/DCF!C50 -> 1.0401546 | D27: =IF(DCF!C49/DCF!C50<0.5,"Value low: revisit",IF(DCF!C49/DCF!C50>2,"Value high: revisit","Within 0.5x-2x")) -> Within 0.5x-2x

Sheet Checks
B2: Model Checks
B3: Ties the workbook to the aswath-finance engine (ginzu.py, calibrated to Damodaran's spreadsheets). Engine values are hard-coded at export; they are only comparable in the base state.
B5: # | C5: Check | D5: Workbook | E5: Engine / rule | F5: Result | G5: Note
B6: 1 | C6: Model in base state (flex cells neutral, scenario 1) | D6: =IF(AND(Sensitivity!$C$5=0,Sensitivity!$C$6=0,Sensitivity!$C$7=0,Sensitivity!$C$8=0,Sensitivity!$C$9=0,Scenarios!$D$5=1),"Base","Flexed") -> Base | E6: ="Base" -> Base | F6: =D6=E6 -> TRUE | G6: Engine tie-outs apply in the base state only
B7: 2 | C7: Value per share ties to engine | D7: =ValuePerShare -> 757.31576 | E7: 757.31576 | F7: =IF(AND(Sensitivity!$C$5=0,Sensitivity!$C$6=0,Sensitivity!$C$7=0,Sensitivity!$C$8=0,Sensitivity!$C$9=0,Scenarios!$D$5=1),ABS(D7-E7)<0.005,TRUE) -> TRUE | G7: ginzu.py value_per_share
B8: 3 | C8: Initial cost of capital ties to engine | D8: =WACC_Initial -> 0.085061237 | E8: 0.085061237 | F8: =IF(AND(Sensitivity!$C$5=0,Sensitivity!$C$6=0,Sensitivity!$C$7=0,Sensitivity!$C$8=0,Sensitivity!$C$9=0,Scenarios!$D$5=1),ABS(D8-E8)<0.000001,TRUE) -> TRUE | G8: cost_of_capital.py / input
B9: 4 | C9: Scenario values tie to engine (max abs difference) | D9: =MAX(ABS(Scenarios!K9-841.905092526385),ABS(Scenarios!K10-672.726431065466),ABS(Scenarios!K11-661.030775655843),ABS(Scenarios!K12-842.29276888124),ABS(Scenarios!K13-654.982885913935),ABS(Scenarios!K14-859.648637677916),ABS(Scenarios!K15-588.699264120359),ABS(Scenarios!K16-674.728610976075),ABS(Scenarios!K17-719.608933470604)) -> 7.9580786e-13 | E9: 0 | F9: =IF(AND(Sensitivity!$C$5=0,Sensitivity!$C$6=0,Sensitivity!$C$7=0,Sensitivity!$C$8=0,Sensitivity!$C$9=0,Scenarios!$D$5=1),D9<0.01,TRUE) -> TRUE | G9: ginzu.py on each scenario's inputs
B10: 5 | C10: Sensitivity table 1 centre = base value | D10: =Sensitivity!E18 -> 757.31576 | E10: =ValuePerShare -> 757.31576 | F10: =IF(AND(Sensitivity!$C$5=0,Sensitivity!$C$6=0,Sensitivity!$C$7=0,Sensitivity!$C$8=0,Sensitivity!$C$9=0,Scenarios!$D$5=1),ABS(D10-E10)<0.005,TRUE) -> TRUE | G10: Excel data table (recalculates on open)
B11: 6 | C11: Sensitivity table 2 centre = base value | D11: =Sensitivity!E31 -> 757.31576 | E11: =ValuePerShare -> 757.31576 | F11: =IF(AND(Sensitivity!$C$5=0,Sensitivity!$C$6=0,Sensitivity!$C$7=0,Sensitivity!$C$8=0,Sensitivity!$C$9=0,Scenarios!$D$5=1),ABS(D11-E11)<0.005,TRUE) -> TRUE
B12: 7 | C12: Equity bridge adds up | D12: =DCF!C46 -> 1929261.9 | E12: =DCF!C39-DCF!C40-DCF!C41+DCF!C42-DCF!C43+DCF!C44+DCF!C45 -> 1929261.9 | F12: =ABS(D12-E12)<0.001 -> TRUE
C14: ALL CHECKS PASS | F14: =COUNTIF(F6:F12,FALSE)=0 -> TRUE
B16: Ginzu rules (warnings, not errors: Damodaran states them outright)
C17: Terminal growth <= riskfree rate after year 10 | D17: =DCF!C31 -> 0.0528 | E17: =DCF!C28 -> 0.0528 | F17: =IF(D17<=E17+0.0000001,"OK","WARNING") -> OK
C18: Terminal ROIC >= terminal cost of capital (else growth destroys value) | D18: =DCF!C32 -> 0.15 | E18: =DCF!C30 -> 0.0948 | F18: =IF(D18>=E18-0.0000001,"OK","WARNING") -> OK
C19: Value / price within the Ginzu 0.5x-2x Diagnostics flag | D19: =DCF!C49/DCF!C50 -> 1.0401546 | E19: 0.5x-2x | F19: =IF(AND(D19>=0.5,D19<=2),"OK","WARNING") -> OK

Sheet Sources
B2: Sources, Methodology & Notes
B3: Every input traces to a filing, market data, or Damodaran's own model/data
B5: Sources and notes
C6: revenues | D6: FILING: TTM to 2026-06-30 = FY2025 200,966 + H1 2026 117,111 - H1 2025 89,830 (10-K 2025; 10-Q 2026-06-30), https://www.sec.gov/Archives/edgar/data/1326801/000162828026050705/meta-20260630.htm
C7: ebit | D7: FILING: TTM income from operations = 83,276 + 41,647 - 37,997 (includes $2.4bn of Q2-2026 legal charges)
C8: rd | D8: FILING: R&D TTM 57,372 + 39,354 - 25,092 = 71,634; FY2025 57,372, FY2024 43,873, FY2023 38,483 (10-K); 3-year life = DAMODARAN Meta2024 input
C9: book_equity | D9: FILING: total stockholders' equity 261,221 at 2026-06-30
C10: book_debt | D10: FILING: long-term debt 83,664 + operating lease liabilities 2,425 + 26,229 = 112,318 at 2026-06-30 (finance lease liabilities sit in other liabilities and are not added)
C11: cash | D11: FILING: cash and cash equivalents 15,462 + marketable securities 74,798 at 2026-06-30 (restricted cash excluded)
C12: non_operating_assets | D12: FILING: non-marketable equity investments 30,157 at 2026-06-30 (cross holdings)
C13: minority_interests | D13: FILING: none
C14: shares_outstanding | D14: FILING: 10-Q cover, 2026-07-24: Class A 2,205,128,509 + Class B 342,377,716 = 2,547.5 million
C15: price | D15: MARKET: META close 2026-10-02, $728.08 (https://stockanalysis.com/stocks/meta/)
C16: effective_tax_rate | D16: FILING/GUIDANCE: 16%, the midpoint of the company's 15-17% outlook for the rest of 2026 (Q2-2026 rate 15.5%); the TTM rate is distorted by a $15.93bn Q3-2025 charge and an $8.03bn Q1-2026 benefit
C17: marginal_tax_rate | D17: DAMODARAN Meta2024 input (25%)
... C31: Notes | D31: Story: Damodaran's Feb-2024 Meta story (12% revenue growth, 40% target margin, 15% terminal ROIC, industry-average cost of capital) is kept; the base year and the reinvestment efficiency are updated because AI capital spending ($130-145bn guided for 2026) has cut sales-to-capital to about 0.5.
D32: Damodaran's May-2026 post flags Meta's AI spending as the key test of Zuckerberg's big bets, with shareholders reduced to bystanders by the dual-class structure.
D33: Analyst consensus figures (revenue, price target) are third-party data from S&P Global via StockAnalysis, shown for reference.
C34: Methodology | D34: FCFF DCF transcribed from Damodaran's fcffsimpleginzu spreadsheet (ginzu.py, which reproduces 31 published Damodaran valuations); cost of capital from Damodaran's worksheet (cost_of_capital.py).
D35: Data: Damodaran fcffsimpleginzu.xlsx (pages.stern.nyu.edu/~adamodar), Updated January 1, 2026.
C36: Disclaimer | D36: Educational application of Damodaran's public framework and data. Not investment advice, not a recommendation, and not affiliated with or endorsed by Damodaran or any bank.
