Workbook
Name AllChecksPass: Checks!$F$19
Name OperatingAssets: DCF!$C$39
Name SharePrice: Inputs!$C$7
Name ValuePerShare: DCF!$C$49
Name WACC_Initial: WACC!$C$45

Sheet Cover
C3: Space Exploration Technologies Corp. (NASDAQ: SPCX)
C5: Intrinsic Valuation: Damodaran FCFF (Ginzu) Framework
C7: Valuation date: 25 September 2026 | $ in millions except per share | For internal discussion
C10: Headline
C11: Intrinsic value per share | D11: =ValuePerShare -> 81.404733
C12: Share price (25-Sep-2026) | D12: =SharePrice -> 148.68
C13: Price as % of value | D13: =DCF!C51 -> 1.8264294
C14: Model checks | D14: =IF(AllChecksPass,"All checks pass","CHECK FAILURES - see Checks tab") -> All checks pass
C16: Contents
C17: Summary | D17: Key outputs, EV-to-equity bridge, scenarios, football field, value walk
C18: Inputs | D18: All hard-coded inputs with sources (blue)
C19: Scenarios | D19: Live scenario selector and scenario table
C20: Sensitivity | D20: Live data tables: cost of capital, revenue x margin, riskfree
C21: WACC | D21: Cost of capital build (Damodaran's method)
C22: Segments | D22: Segment revenue, margin and reinvestment build
C23: DCF | D23: FCFF projection, terminal value and equity bridge
C24: Diagnostics | D24: Ginzu diagnostic checks vs industry
C25: Checks | D25: Tie-out to the calibrated engine and to the Ginzu rules
C26: Sources | D26: Sources, methodology, judgment calls, disclaimer
C28: Colour convention
C29: Blue: hard-coded input
C30: Black: formula
C31: Green: link to another sheet
C32: Yellow fill: flex / selector cell (keep at base)
C34: Educational application of Damodaran's public framework and data; not investment advice. See Sources.

Sheet Summary
B2: Valuation Summary: Space Exploration Technologies Corp. (NASDAQ: SPCX)
B3: Intrinsic value, Damodaran FCFF framework | Valuation date 25-Sep-2026 | $ in millions except per share
B5: Key outputs | F5: Enterprise value to equity bridge | T5: Chart data: football field ($ per share)
B6: Intrinsic value per share ($) | C6: =ValuePerShare -> 81.404733 | F6: Value of operating assets | G6: =DCF!C39 -> 1012414.3 | T6: Reference | U6: Low | V6: High - low | W6: High
B7: Current share price ($) | C7: =SharePrice -> 148.68 | F7: Less: debt | G7: =-DCF!C40 -> -39364 | T7: 52-week trading range | U7: =Inputs!$C$9 -> 104.83 | V7: =W7-U7 -> 120.81 | W7: =Inputs!$C$10 -> 225.64
B8: Upside / (downside) to value | C8: =DCF!C52 -> -0.45248363 | F8: Less: minority interests | G8: =-DCF!C41 -> 0 | T8: Analyst average target (third party) | U8: =Inputs!$C$11-1 -> 221.42 | V8: =W8-U8 -> 2 | W8: =Inputs!$C$11+1 -> 223.42
B9: Price as % of value | C9: =DCF!C51 -> 1.8264294 | F9: Plus: cash & marketable securities | G9: =DCF!C42 -> 100009 | T9: DCF: cost of capital sensitivity | U9: =MIN(Sensitivity!C14:G22) -> 58.574212 | V9: =W9-U9 -> 64.202602 | W9: =MAX(Sensitivity!C14:G22) -> 122.77681
B10: Market capitalization | C10: =SharePrice*Inputs!$C$8 -> 1959867.1 | F10: Plus: non-operating assets | G10: =DCF!C43 -> 0 | T10: DCF: revenue x margin sensitivity | U10: =MIN(Sensitivity!C28:G34) -> 46.487603 | V10: =W10-U10 -> 152.81737 | W10: =MAX(Sensitivity!C28:G34) -> 199.30497
B11: Market enterprise value | C11: =C10+Inputs!$C$16-Inputs!$C$15 -> 1899222.1 | F11: Plus: IPO proceeds not yet received | G11: =DCF!C44 -> 0 | T11: DCF: scenario range | U11: =MIN(Scenarios!K8:K19) -> 62.577651 | V11: =W11-U11 -> 37.654165 | W11: =MAX(Scenarios!K8:K19) -> 100.23182
B12: Intrinsic value of operating assets | C12: =OperatingAssets -> 1012414.3 | F12: Less: employee options | G12: =-DCF!C46 -> 0 | T12: Damodaran June 2026 value | U12: =Inputs!$C$12-1 -> 96.83 | V12: =W12-U12 -> 2 | W12: =Inputs!$C$12+1 -> 98.83
B13: Intrinsic value of equity | C13: =DCF!C47 -> 1073059.3 | F13: Value of equity in common stock | G13: =DCF!C47 -> 1073059.3 | T13: DCF base case | U13: =ValuePerShare-1 -> 80.404733 | V13: =W13-U13 -> 2 | W13: =ValuePerShare+1 -> 82.404733
B14: Initial / terminal cost of capital | C14: =TEXT(DCF!C27,"0.00%")&" / "&TEXT(DCF!C28,"0.00%") -> 10.42% / 8.86% | F14: Shares outstanding (m) | G14: =DCF!C48 -> 13181.78 | T14: Current share price | U14: =SharePrice-1 -> 147.68 | V14: =W14-U14 -> 2 | W14: =SharePrice+1 -> 149.68
B15: Terminal growth (= riskfree) | C15: =DCF!C31 -> 0.0517 | F15: Value per share ($) | G15: =DCF!C49 -> 81.404733
B16: 2036 revenue (model) | C16: =DCF!M7 -> 420000
B17: Damodaran June 2026 value per share ($) | C17: =Inputs!$C$12 -> 97.83 | T17: Chart data: value walk waterfall ($ per share)
B18: Revenue breakeven vs price (x the 2036 targets) | C18: 1.893 | T18: Step | U18: Base | V18: Decrease | W18: Increase | X18: Total
B19: Breakeven computed by the engine (spacex_model.py); the same ratio sits in Sensitivity, row 33. | T19: June 2026 | X19: =C39 -> 97.8277
T20: Roll-forward | U20: =MIN(C40,C39) -> 97.7667 | V20: =MAX(C39-C40,0) -> 0.061 | W20: =MAX(C40-C39,0) -> 0
B21: Scenario analysis (live; one change at a time) | T21: Riskfree | U21: =MIN(C41,C40) -> 88.7771 | V21: =MAX(C40-C41,0) -> 8.9896 | W21: =MAX(C41-C40,0) -> 0
B22: Scenario | C22: Value / share | D22: vs price | T22: Beta weights | U22: =MIN(C42,C41) -> 81.2343 | V22: =MAX(C41-C42,0) -> 7.5428 | W22: =MAX(C42-C41,0) -> 0
B23: =Scenarios!C8 -> Base case | C23: =Scenarios!K8 -> 81.404733 | D23: =Scenarios!L8 -> -0.45248363 | T23: Country ERPs | U23: =MIN(C43,C42) -> 81.2343 | V23: =MAX(C42-C43,0) -> 0 | W23: =MAX(C43-C42,0) -> 0.1704
B24: =Scenarios!C9 -> June-model beta weights (xAI at $100m, stale) | C24: =Scenarios!K9 -> 88.913607 | D24: =Scenarios!L9 -> -0.40198004 | T24: Sept 2026 | X24: =C43 -> 81.4047
B25: =Scenarios!C10 -> Riskfree back at June 4.56% (terminal coc 8.25%) | C25: =Scenarios!K10 -> 89.585588 | D25: =Scenarios!L10 -> -0.3974604
B26: =Scenarios!C11 -> Terminal cost of capital = June model's 8.25% | C26: =Scenarios!K11 -> 95.888839 | D26: =Scenarios!L11 -> -0.35506565
B27: =Scenarios!C12 -> Terminal cost of capital = rf + mature ERP 9.37% | C27: =Scenarios!K12 -> 72.518012 | D27: =Scenarios!L12 -> -0.51225442
B28: =Scenarios!C13 -> xAI 2036 revenue $80bn (April 2026 view) | C28: =Scenarios!K13 -> 73.140362 | D28: =Scenarios!L13 -> -0.50806859
B29: =Scenarios!C14 -> xAI 2036 revenue $240bn | C29: =Scenarios!K14 -> 89.669105 | D29: =Scenarios!L14 -> -0.39689867
B30: =Scenarios!C15 -> Starlink target margin 50% | C30: =Scenarios!K15 -> 75.135279 | D30: =Scenarios!L15 -> -0.49465107
B31: =Scenarios!C16 -> Starlink target margin 70% | C31: =Scenarios!K16 -> 87.674188 | D31: =Scenarios!L16 -> -0.41031619
B32: =Scenarios!C17 -> xAI sales-to-capital 0.5 in yrs 1-5 (H1-26 capex pace) | C32: =Scenarios!K17 -> 77.437048 | D32: =Scenarios!L17 -> -0.47916971
B33: =Scenarios!C18 -> All 2036 revenue targets x0.75 | C33: =Scenarios!K18 -> 62.577651 | D33: =Scenarios!L18 -> -0.57911185
B34: =Scenarios!C19 -> All 2036 revenue targets x1.25 | C34: =Scenarios!K19 -> 100.23182 | D34: =Scenarios!L19 -> -0.32585542
B37: Value walk: Damodaran's June 2026 value to this update ($ per share)
B38: Step (engine attribution; order-dependent) | C38: Value / share | D38: Change
B39: Damodaran June 2026 value (IPO at $135) | C39: 97.8277
B40: Roll-forward: TTM base year, IPO cash, 13.18bn shares | C40: 97.7667 | D40: =C40-C39 -> -0.061
B41: Riskfree 4.56% -> 5.17% (terminal 8.25% -> 8.86%) | C41: 88.7771 | D41: =C41-C40 -> -8.9896
B42: Beta weights: April mix -> TTM segment revenues | C42: 81.2343 | D42: =C42-C41 -> -7.5428
B43: Country ERPs: Jan-2026 -> July-2026 (final) | C43: 81.4047 | D43: =C43-C42 -> 0.1704

Sheet Inputs
B2: Inputs & Assumptions
B3: $ in millions except per-share data | Blue = hard-coded input (source in column J) | Valuation date 25-Sep-2026
B5: Market data
B6: Valuation date | C6: 46290 | J6: Close of 25-Sep-2026 (last trading day before analysis)
B7: Share price ($) | C7: 148.68 | J7: StockAnalysis, close 25-Sep-2026 4:00pm ET: https://stockanalysis.com/stocks/spcx/
B8: Shares outstanding (m) | C8: 13181.78 | J8: 10-Q cover 28-Jul-2026: Class A 7,696.29m + Class B 5,485.49m (StockAnalysis shows 13.57bn)
B9: 52-week low ($) | C9: 104.83 | J9: StockAnalysis, 25-Sep-2026
B10: 52-week high ($) | C10: 225.64 | J10: StockAnalysis, 25-Sep-2026
B11: Analyst average price target ($) | C11: 222.42 | J11: StockAnalysis: consensus Buy, 35 analysts (third-party aggregate)
B12: Damodaran June 2026 value per share ($) | C12: 97.83 | J12: Damodaran, SpaceX2026IPOUpdated.xlsx (reproduced exactly by the engine)
B14: Balance sheet & income (Q2-2026 10-Q; TTM to 30-Jun-2026)
B15: Cash & marketable securities | C15: 100009 | J15: FILING: cash 93,522 + marketable securities 6,487 at 2026-06-30 (includes the IPO's $85,675m net proceeds, so ipo_proceeds = 0)
B16: Debt incl. finance leases | C16: 39364 | J16: FILING: current 2,525 + long-term 36,839 debt and finance leases at 2026-06-30
B17: Book value of equity | C17: 127224 | J17: FILING: total shareholders' equity 127,224 at 2026-06-30
B18: Minority interests | C18: 0 | J18: Not identified in the 10-Q balance sheet
B19: Non-operating assets (cross holdings) | C19: 0 | J19: None identified
B20: IPO proceeds not yet received | C20: 0 | J20: FILING: cash 93,522 + marketable securities 6,487 at 2026-06-30 (includes the IPO's $85,675m net proceeds, so ipo_proceeds = 0)
B21: Operating income (EBIT), TTM | C21: -3732 | J21: FILING: FY2025 -2,589 + H1-2026 -2,086 - H1-2025 -943 (10-Q statements of operations)
B22: Interest expense, TTM | C22: 2380 | J22: FILING: FY2025 1,945 + H1-2026 1,293 - H1-2025 858
B23: Revenue, FY2025 | C23: 18674 | J23: Damodaran's June 2026 model (prospectus FY2025 segment revenues)
B24: Net operating loss carried forward | C24: 0 | J24: Ginzu default (no NOL override)
B25: Value of employee options | C25: 0 | J25: DAMODARAN June inputs (effective 10%, marginal 25%; options excluded as in Damodaran's model; option counts not disclosed in the 10-Q)
B27: R&D capitalization (Ginzu R&D converter)
B28: R&D expense, current (TTM) | C28: 12190 | J28: FILING: FY2025 8,643 + H1-2026 7,062 - H1-2025 3,515; earlier years = Damodaran's June inputs
B29: R&D expense, year -1 | C29: 3464 | J29: Damodaran's June 2026 model inputs
B30: R&D expense, year -2 | C30: 2105 | J30: Damodaran's June 2026 model inputs
B31: R&D expense, year -3 | C31: 1800 | J31: Damodaran's June 2026 model inputs
B32: R&D expense, year -4 | C32: 1600 | J32: Damodaran's June 2026 model inputs
B33: R&D expense, year -5 | C33: 1200 | J33: Damodaran's June 2026 model inputs
B34: Amortizable life (years) | C34: 5 | J34: Damodaran's June 2026 model
B36: Taxes and discount-rate inputs
B37: Effective tax rate | C37: 0.1 | J37: DAMODARAN June inputs (effective 10%, marginal 25%; options excluded as in Damodaran's model; option counts not disclosed in the 10-Q)
B38: Marginal tax rate | C38: 0.25 | J38: DAMODARAN June inputs (effective 10%, marginal 25%; options excluded as in Damodaran's model; option counts not disclosed in the 10-Q)
B39: Riskfree rate (US 10-year Treasury) | C39: 0.0517 | J39: MARKET: US 10-year Treasury 5.17% on 2026-09-25 (https://www.cnbc.com/2026/09/25/treasury-yields-bonds-debt.html); Damodaran's company models use the T-bond rate
B40: Mature market ERP | C40: 0.042 | J40: DAMODARAN July 2026 country-risk update: mature market ERP 4.20% (country_risk.py, ctrypremJuly26.xlsx)
B41: Terminal cost of capital | C41: 0.0886 | J41: DAMODARAN 8.25% steady-state choice, moved with the riskfree rate (+0.61pts: 5.17% - 4.56%), as Damodaran's industry-average method adjusts for riskfree changes
B42: Terminal return on capital (ROIC) | C42: 0.15 | J42: Damodaran's June 2026 override (15%)
B43: Probability of failure | C43: 0 | J43: Damodaran's June 2026 model (no failure)
B44: Distress proceeds (% of fair value) | C44: 0.5 | J44: Ginzu template default
B45: June 2026 model riskfree rate (reference) | C45: 0.0456 | J45: Damodaran's June 2026 model
...

Sheet Scenarios
B2: Scenario Analysis
B3: One change at a time vs the base case (same set as spacex_model.py --sensitivity). Set the active scenario in D5; column K is a live data table.
C5: Active scenario (enter 1-12) | D5: 1 | E5: =INDEX($C$8:$C$19,$D$5) -> Base case
N6: Data table (Excel What-If; do not edit)
B7: # | C7: Scenario | D7: Riskfree | E7: Terminal cost of capital | F7: Beta weight set (1=TTM, 2=June) | G7: xAI 2036 revenue | H7: Starlink target margin | I7: xAI sales/capital yrs 1-5 | J7: 2036 revenue multiplier | K7: Value / share | L7: vs price | O7: =ValuePerShare -> 81.404733
B8: 1 | C8: Base case | D8: =Inputs!$C$39 -> 0.0517 | E8: =Inputs!$C$41 -> 0.0886 | F8: 1 | G8: =Inputs!$D$52 -> 160000 | H8: =Inputs!$F$51 -> 0.6 | I8: =Inputs!$G$52 -> 1.5 | J8: 1 | K8: =O8 -> 81.404733 | L8: =K8/Inputs!$C$7-1 -> -0.45248363 | N8: 1 | O8: 81.404733
B9: 2 | C9: June-model beta weights (xAI at $100m, stale) | D9: =$D$8 -> 0.0517 | E9: =$E$8 -> 0.0886 | F9: 2 | G9: =$G$8 -> 160000 | H9: =$H$8 -> 0.6 | I9: =$I$8 -> 1.5 | J9: =$J$8 -> 1 | K9: =O9 -> 88.913607 | L9: =K9/Inputs!$C$7-1 -> -0.40198004 | N9: 2 | O9: 88.913607
B10: 3 | C10: Riskfree back at June 4.56% (terminal coc 8.25%) | D10: =Inputs!$C$45 -> 0.0456 | E10: =Inputs!$C$46 -> 0.0825 | F10: =$F$8 -> 1 | G10: =$G$8 -> 160000 | H10: =$H$8 -> 0.6 | I10: =$I$8 -> 1.5 | J10: =$J$8 -> 1 | K10: =O10 -> 89.585588 | L10: =K10/Inputs!$C$7-1 -> -0.3974604 | N10: 3 | O10: 89.585588
B11: 4 | C11: Terminal cost of capital = June model's 8.25% | D11: =$D$8 -> 0.0517 | E11: =Inputs!$C$46 -> 0.0825 | F11: =$F$8 -> 1 | G11: =$G$8 -> 160000 | H11: =$H$8 -> 0.6 | I11: =$I$8 -> 1.5 | J11: =$J$8 -> 1 | K11: =O11 -> 95.888839 | L11: =K11/Inputs!$C$7-1 -> -0.35506565 | N11: 4 | O11: 95.888839
B12: 5 | C12: Terminal cost of capital = rf + mature ERP 9.37% | D12: =$D$8 -> 0.0517 | E12: =Inputs!$C$39+Inputs!$C$40 -> 0.0937 | F12: =$F$8 -> 1 | G12: =$G$8 -> 160000 | H12: =$H$8 -> 0.6 | I12: =$I$8 -> 1.5 | J12: =$J$8 -> 1 | K12: =O12 -> 72.518012 | L12: =K12/Inputs!$C$7-1 -> -0.51225442 | N12: 5 | O12: 72.518012
B13: 6 | C13: xAI 2036 revenue $80bn (April 2026 view) | D13: =$D$8 -> 0.0517 | E13: =$E$8 -> 0.0886 | F13: =$F$8 -> 1 | G13: 80000 | H13: =$H$8 -> 0.6 | I13: =$I$8 -> 1.5 | J13: =$J$8 -> 1 | K13: =O13 -> 73.140362 | L13: =K13/Inputs!$C$7-1 -> -0.50806859 | N13: 6 | O13: 73.140362
B14: 7 | C14: xAI 2036 revenue $240bn | D14: =$D$8 -> 0.0517 | E14: =$E$8 -> 0.0886 | F14: =$F$8 -> 1 | G14: 240000 | H14: =$H$8 -> 0.6 | I14: =$I$8 -> 1.5 | J14: =$J$8 -> 1 | K14: =O14 -> 89.669105 | L14: =K14/Inputs!$C$7-1 -> -0.39689867 | N14: 7 | O14: 89.669105
B15: 8 | C15: Starlink target margin 50% | D15: =$D$8 -> 0.0517 | E15: =$E$8 -> 0.0886 | F15: =$F$8 -> 1 | G15: =$G$8 -> 160000 | H15: 0.5 | I15: =$I$8 -> 1.5 | J15: =$J$8 -> 1 | K15: =O15 -> 75.135279 | L15: =K15/Inputs!$C$7-1 -> -0.49465107 | N15: 8 | O15: 75.135279
B16: 9 | C16: Starlink target margin 70% | D16: =$D$8 -> 0.0517 | E16: =$E$8 -> 0.0886 | F16: =$F$8 -> 1 | G16: =$G$8 -> 160000 | H16: 0.7 | I16: =$I$8 -> 1.5 | J16: =$J$8 -> 1 | K16: =O16 -> 87.674188 | L16: =K16/Inputs!$C$7-1 -> -0.41031619 | N16: 9 | O16: 87.674188
B17: 10 | C17: xAI sales-to-capital 0.5 in yrs 1-5 (H1-26 capex pace) | D17: =$D$8 -> 0.0517 | E17: =$E$8 -> 0.0886 | F17: =$F$8 -> 1 | G17: =$G$8 -> 160000 | H17: =$H$8 -> 0.6 | I17: 0.5 | J17: =$J$8 -> 1 | K17: =O17 -> 77.437048 | L17: =K17/Inputs!$C$7-1 -> -0.47916971 | N17: 10 | O17: 77.437048
B18: 11 | C18: All 2036 revenue targets x0.75 | D18: =$D$8 -> 0.0517 | E18: =$E$8 -> 0.0886 | F18: =$F$8 -> 1 | G18: =$G$8 -> 160000 | H18: =$H$8 -> 0.6 | I18: =$I$8 -> 1.5 | J18: 0.75 | K18: =O18 -> 62.577651 | L18: =K18/Inputs!$C$7-1 -> -0.57911185 | N18: 11 | O18: 62.577651
B19: 12 | C19: All 2036 revenue targets x1.25 | D19: =$D$8 -> 0.0517 | E19: =$E$8 -> 0.0886 | F19: =$F$8 -> 1 | G19: =$G$8 -> 160000 | H19: =$H$8 -> 0.6 | I19: =$I$8 -> 1.5 | J19: 1.25 | K19: =O19 -> 100.23182 | L19: =K19/Inputs!$C$7-1 -> -0.32585542 | N19: 12 | O19: 100.23182
B21: Live drivers (active scenario, feed the model)
C22: Active scenario values | D22: =INDEX(D$8:D$19,$D$5) -> 0.0517 | E22: =INDEX(E$8:E$19,$D$5) -> 0.0886 | F22: =INDEX(F$8:F$19,$D$5) -> 1 | G22: =INDEX(G$8:G$19,$D$5) -> 160000 | H22: =INDEX(H$8:H$19,$D$5) -> 0.6 | I22: =INDEX(I$8:I$19,$D$5) -> 1.5 | J22: =INDEX(J$8:J$19,$D$5) -> 1
C24: Engine check (spacex_model.py --sensitivity): scenario values must equal column K; see Checks.

Sheet Sensitivity
B2: Sensitivity Analysis
B3: Live Excel data tables on value per share ($). Flex cells (yellow) must stay neutral for the base case; the data tables vary them.
B4: Flex cells (neutral values = base case)
B5: Change in initial cost of capital | C5: 0
B6: Change in terminal cost of capital | C6: 0
B7: 2036 revenue multiplier (all segments) | C7: 1
B8: Change in target margin (all segments) | C8: 0
B9: Change in riskfree rate | C9: 0
B11: Value per share: initial vs terminal cost of capital (change from base)
B12: Rows: change in initial cost of capital | Columns: change in terminal cost of capital
B13: =ValuePerShare -> 81.404733 | C13: -0.01 | D13: -0.005 | E13: 0 | F13: 0.005 | G13: 0.01 | I13: Shaded green: value at or above the current share price
B14: -0.02 | C14: 122.77681 | D14: 104.90484 | E14: 91.868978 | F14: 81.938055 | G14: 74.119127 | I14: Current share price
B15: -0.015 | C15: 119.03495 | D15: 101.73149 | E15: 89.110298 | F15: 79.495267 | G15: 71.925042 | I15: =SharePrice -> 148.68
B16: -0.01 | C16: 115.42578 | D16: 98.670544 | E16: 86.449225 | F16: 77.138817 | G16: 69.808424
B17: -0.005 | C17: 111.94406 | D17: 95.717582 | E17: 83.881927 | F17: 74.865316 | G17: 67.766234
B18: 0 | C18: 108.58482 | D18: 92.868374 | E18: 81.404733 | F18: 72.671523 | G18: 65.795564
B19: 0.005 | C19: 105.34326 | D19: 90.118872 | E19: 79.014133 | F19: 70.554333 | G19: 63.893634
B20: 0.01 | C20: 102.21481 | D20: 87.465204 | E20: 76.706766 | F20: 68.510777 | G20: 62.057781
B21: 0.015 | C21: 99.195092 | D21: 84.903662 | E21: 74.479413 | F21: 66.538011 | G21: 60.285454
B22: 0.02 | C22: 96.279908 | D22: 82.430696 | E22: 72.328996 | F22: 64.633312 | G22: 58.574212
B25: Value per share: 2036 revenue multiplier vs target-margin change (all segments)
B26: Rows: 2036 revenue multiplier (1.89x = breakeven vs price) | Columns: change in target margins
B27: =ValuePerShare -> 81.404733 | C27: -0.1 | D27: -0.05 | E27: 0 | F27: 0.05 | G27: 0.1
B28: 0.75 | C28: 46.487603 | D28: 54.532627 | E28: 62.577651 | F28: 70.622675 | G28: 78.667698
B29: 1 | C29: 60.014314 | D29: 70.709524 | E29: 81.404733 | F29: 92.099943 | G29: 102.79515
B30: 1.25 | C30: 73.541025 | D30: 86.886421 | E30: 100.23182 | F30: 113.57721 | G30: 126.92261
B31: 1.5 | C31: 87.067736 | D31: 103.06332 | E31: 119.0589 | F31: 135.05448 | G31: 151.05006
B32: 1.75 | C32: 100.59445 | D32: 119.24021 | E32: 137.88598 | F32: 156.53175 | G32: 175.17752
B33: 1.893 | C33: 108.33173 | D33: 128.4934 | E33: 148.65507 | F33: 168.81675 | G33: 188.97842
B34: 2 | C34: 114.12116 | D34: 135.41711 | E34: 156.71306 | F34: 178.00902 | G34: 199.30497
B37: Riskfree rate: value per share and cost of capital (terminal cost of capital and growth move with it)
B38: Change in riskfree rate | C38: Value / share | D38: Initial WACC
B39: (base) | C39: =ValuePerShare -> 81.404733 | D39: =WACC_Initial -> 0.10416279
B40: -0.015 | C40: 102.71783 | D40: 0.089228231
B41: -0.01 | C41: 95.158209 | D41: 0.094205823
B42: -0.005 | C42: 88.063074 | D42: 0.099184015
B43: 0 | C43: 81.404733 | D43: 0.10416279
B44: 0.005 | C44: 75.157179 | D44: 0.10914213
B45: 0.01 | C45: 69.295981 | D45: 0.11412203
B46: 0.015 | C46: 63.798184 | D46: 0.11910246

Sheet WACC
B2: Cost of Capital
B3: Damodaran's method: multi-business unlevered beta (revenue x industry EV/Sales weights), ERP by operating country, rating-based cost of debt, market-value weights
B5: Unlevered beta: multi-business
B6: Business | C6: Revenue (live) | D6: EV/Sales | E6: Estimated value | F6: Weight | G6: Unlevered beta | H6: Weighted beta
B7: =Inputs!B58 -> Aerospace/Defense | C7: =IF(Scenarios!$F$22=2,Inputs!$F$58,Inputs!$C$58) -> 4056 | D7: =Inputs!$E$58 -> 3.3852461 | E7: =C7*D7 -> 13730.558 | F7: =E7/$E$10 -> 0.14328149 | G7: =Inputs!$D$58 -> 1.1666843 | H7: =F7*G7 -> 0.16716427
B8: =Inputs!B59 -> Telecom. Services | C8: =IF(Scenarios!$F$22=2,Inputs!$F$59,Inputs!$C$59) -> 13873 | D8: =Inputs!$E$59 -> 2.2630078 | E8: =C8*D8 -> 31394.707 | F8: =E8/$E$10 -> 0.3276109 | G8: =Inputs!$D$59 -> 0.49625572 | H8: =F8*G8 -> 0.16257878
B9: =Inputs!B60 -> Software (System & Application) | C9: =IF(Scenarios!$F$22=2,Inputs!$F$60,Inputs!$C$60) -> 5115 | D9: =Inputs!$E$60 -> 9.9128028 | E9: =C9*D9 -> 50703.986 | F9: =E9/$E$10 -> 0.52910761 | G9: =Inputs!$D$60 -> 1.3309503 | H9: =F9*G9 -> 0.70421591
B10: Total / unlevered beta | C10: =SUM(C7:C9) -> 23044 | E10: =SUM(E7:E9) -> 95829.251 | F10: =SUM(F7:F9) -> 1 | H10: =SUM(H7:H9) -> 1.033959
B12: Equity risk premium: operating-country weights
B13: Country | C13: Revenue | D13: Weight | E13: ERP | F13: Weighted ERP
B14: =Inputs!B63 -> United States | C14: =Inputs!$C$63 -> 15207 | D14: =C14/$C$17 -> 0.48221081 | E14: =Inputs!$D$63 -> 0.0442 | F14: =D14*E14 -> 0.021313718
B15: =Inputs!B64 -> China | C15: =Inputs!$C$64 -> 6662 | D15: =C15/$C$17 -> 0.21125063 | E15: =Inputs!$D$64 -> 0.0507 | F15: =D15*E15 -> 0.010710407
B16: =Inputs!B65 -> Rest of the world | C16: =Inputs!$C$65 -> 9667 | D16: =C16/$C$17 -> 0.30653856 | E16: =Inputs!$D$65 -> 0.0618 | F16: =D16*E16 -> 0.018944083
B17: Total / weighted ERP | C17: =SUM(C14:C16) -> 31536 | D17: =SUM(D14:D16) -> 1 | F17: =SUM(F14:F16) -> 0.050968208
B19: Cost of debt (actual rating) and market value of debt
B20: Riskfree rate (live) | C20: =Scenarios!$D$22+Sensitivity!$C$9 -> 0.0517
B21: Bond rating | C21: =Inputs!$C$67 -> Ba2/BB
B22: Default spread | C22: =Inputs!$C$68 -> 0.018395
B23: Pre-tax cost of debt | C23: =C20+C22 -> 0.070095
B24: Book value of debt | C24: =Inputs!$C$16 -> 39364
B25: Interest expense (TTM) | C25: =Inputs!$C$22 -> 2380
B26: Average maturity (years) | C26: =Inputs!$C$69 -> 3
B27: Market value of debt | C27: =C25*(1-(1+C23)^(-C26))/C23+C24/(1+C23)^C26 -> 38368.981
B29: Capital structure (market values)
B30: Share price | C30: =Inputs!$C$7 -> 148.68
B31: Shares outstanding (m) | C31: =Inputs!$C$8 -> 13181.78
B32: Market value of equity | C32: =C30*C31 -> 1959867.1
B33: Market value of debt | C33: =C27 -> 38368.981
B34: Debt / equity | C34: =C33/C32 -> 0.019577339
B35: Debt / capital | C35: =C33/(C32+C33) -> 0.019201426
B36: Equity / capital | C36: =C32/(C32+C33) -> 0.98079857
B38: Cost of capital
B39: Unlevered beta | C39: =H10 -> 1.033959
B40: Marginal tax rate | C40: =Inputs!$C$38 -> 0.25
B41: Levered beta = Bu x (1 + (1 - t) x D/E) | C41: =C39*(1+(1-C40)*C34) -> 1.0491406
B42: Equity risk premium | C42: =F17 -> 0.050968208
B43: Cost of equity = Rf + Bl x ERP | C43: =C20+C41*C42 -> 0.10517282
B44: After-tax cost of debt | C44: =C23*(1-C40) -> 0.05257125
B45: Cost of capital (initial) | C45: =C36*C43+C35*C44 -> 0.10416279

Sheet Segments
B2: Segment Build
B3: Damodaran's June 2026 SpaceX mechanics: revenue steps toward year 5 then the 2036 target; margins converge linearly; reinvestment = revenue change / segment sales-to-capital. $ in millions.
C4: Base (TTM) | D4: Year 1 | E4: Year 2 | F4: Year 3 | G4: Year 4 | H4: Year 5 | I4: Year 6 | J4: Year 7 | K4: Year 8 | L4: Year 9 | M4: Year 10
B5: Year (t) | C5: 0 | D5: 1 | E5: 2 | F5: 3 | G5: 4 | H5: 5 | I5: 6 | J5: 7 | K5: 8 | L5: 9 | M5: 10
B6: Step toward anchor (June 2026 model path) | D6: 0.2 | E6: 0.3 | F6: 0.4 | G6: 0.5 | I6: 0.2 | J6: 0.3 | K6: 0.4 | L6: 0.5
B8: Live segment drivers
B9: Segment | C9: Base revenue | D9: 2036 revenue | E9: Base margin | F9: Target margin | G9: S/C yrs 1-5 | H9: S/C yrs 6-10 | I9: Starts after yr 5
B10: =Inputs!$B$50 -> Launch (Space segment) | C10: =Inputs!$C$50 -> 4056 | D10: =Inputs!$D$50*$C$15 -> 40000 | E10: =Inputs!$E$50 -> 0.08 | F10: =Inputs!$F$50+$C$16 -> 0.45 | G10: =Inputs!$G$50 -> 3 | H10: =Inputs!$H$50 -> 4 | I10: =Inputs!$I$50 -> 0
B11: =Inputs!$B$51 -> Starlink (Connectivity segment) | C11: =Inputs!$C$51 -> 13873 | D11: =Inputs!$D$51*$C$15 -> 120000 | E11: =Inputs!$E$51 -> 0.1 | F11: =Scenarios!$H$22+$C$16 -> 0.6 | G11: =Inputs!$G$51 -> 3 | H11: =Inputs!$H$51 -> 5 | I11: =Inputs!$I$51 -> 0
B12: =Inputs!$B$52 -> xAI (AI segment) | C12: =Inputs!$C$52 -> 5115 | D12: =Scenarios!$G$22*$C$15 -> 160000 | E12: =Inputs!$E$52 -> -0.05 | F12: =Inputs!$F$52+$C$16 -> 0.25 | G12: =Scenarios!$I$22 -> 1.5 | H12: =Inputs!$H$52 -> 2.5 | I12: =Inputs!$I$52 -> 0
B13: =Inputs!$B$53 -> Other (expansion options) | C13: =Inputs!$C$53 -> 0 | D13: =Inputs!$D$53*$C$15 -> 100000 | E13: =Inputs!$E$53 -> 0 | F13: =Inputs!$F$53+$C$16 -> 0.3 | G13: =Inputs!$G$53 -> 5 | H13: =Inputs!$H$53 -> 5 | I13: =Inputs!$I$53 -> 1
B15: Revenue multiplier (scenario x flex) | C15: =Scenarios!$J$22*Sensitivity!$C$7 -> 1
B16: Target margin change (flex) | C16: =Sensitivity!$C$8 -> 0
B17: Year of margin convergence | C17: =Inputs!$C$54 -> 10
B20: =B10 -> Launch (Space segment)
B21: Revenue | C21: =IF($I$10=1,0,$C$10) -> 4056 | D21: =IF($I$10=1,IF(D$5>5,(D$5-5)*$D$10/5,0),C21+($H21-C21)*D$6) -> 6452.2667 | E21: =IF($I$10=1,IF(E$5>5,(E$5-5)*$D$10/5,0),D21+($H21-D21)*E$6) -> 9327.7867 | F21: =IF($I$10=1,IF(F$5>5,(F$5-5)*$D$10/5,0),E21+($H21-E21)*F$6) -> 12011.605 | G21: =IF($I$10=1,IF(G$5>5,(G$5-5)*$D$10/5,0),F21+($H21-F21)*G$6) -> 14024.469 | H21: =IF($I$10=1,IF(H$5>5,(H$5-5)*$D$10/5,0),$C21+($D$10-$C21)/3) -> 16037.333 | I21: =IF($I$10=1,IF(I$5>5,(I$5-5)*$D$10/5,0),H21+($D$10-H21)*I$6) -> 20829.867 | J21: =IF($I$10=1,IF(J$5>5,(J$5-5)*$D$10/5,0),I21+($D$10-I21)*J$6) -> 26580.907 | K21: =IF($I$10=1,IF(K$5>5,(K$5-5)*$D$10/5,0),J21+($D$10-J21)*K$6) -> 31948.544 | L21: =IF($I$10=1,IF(L$5>5,(L$5-5)*$D$10/5,0),K21+($D$10-K21)*L$6) -> 35974.272 | M21: =IF($I$10=1,IF(M$5>5,(M$5-5)*$D$10/5,0),$D$10) -> 40000
B22: Operating margin | C22: =$E$10 -> 0.08 | D22: =IF(D$5>$C$17,$F$10,$F$10-($F$10-$E$10)/$C$17*($C$17-D$5)) -> 0.117 | E22: =IF(E$5>$C$17,$F$10,$F$10-($F$10-$E$10)/$C$17*($C$17-E$5)) -> 0.154 | F22: =IF(F$5>$C$17,$F$10,$F$10-($F$10-$E$10)/$C$17*($C$17-F$5)) -> 0.191 | G22: =IF(G$5>$C$17,$F$10,$F$10-($F$10-$E$10)/$C$17*($C$17-G$5)) -> 0.228 | H22: =IF(H$5>$C$17,$F$10,$F$10-($F$10-$E$10)/$C$17*($C$17-H$5)) -> 0.265 | I22: =IF(I$5>$C$17,$F$10,$F$10-($F$10-$E$10)/$C$17*($C$17-I$5)) -> 0.302 | J22: =IF(J$5>$C$17,$F$10,$F$10-($F$10-$E$10)/$C$17*($C$17-J$5)) -> 0.339 | K22: =IF(K$5>$C$17,$F$10,$F$10-($F$10-$E$10)/$C$17*($C$17-K$5)) -> 0.376 | ... M22: =IF(M$5>$C$17,$F$10,$F$10-($F$10-$E$10)/$C$17*($C$17-M$5)) -> 0.45
B23: Operating income (EBIT) | D23: =D21*D22 -> 754.9152 | E23: =E21*E22 -> 1436.4791 | F23: =F21*F22 -> 2294.2166 | G23: =G21*G22 -> 3197.579 | H23: =H21*H22 -> 4249.8933 | I23: =I21*I22 -> 6290.6197 | J23: =J21*J22 -> 9010.9274 | K23: =K21*K22 -> 12012.653 | ... M23: =M21*M22 -> 18000
B24: Reinvestment | D24: =(D21-C21)/IF(D$5<=5,$G$10,$H$10) -> 798.75556 | E24: =(E21-D21)/IF(E$5<=5,$G$10,$H$10) -> 958.50667 | F24: =(F21-E21)/IF(F$5<=5,$G$10,$H$10) -> 894.60622 | G24: =(G21-F21)/IF(G$5<=5,$G$10,$H$10) -> 670.95467 | H24: =(H21-G21)/IF(H$5<=5,$G$10,$H$10) -> 670.95467 | I24: =(I21-H21)/IF(I$5<=5,$G$10,$H$10) -> 1198.1333 | J24: =(J21-I21)/IF(J$5<=5,$G$10,$H$10) -> 1437.76 | K24: =(K21-J21)/IF(K$5<=5,$G$10,$H$10) -> 1341.9093 | ... M24: =(M21-L21)/IF(M$5<=5,$G$10,$H$10) -> 1006.432
B26: =B11 -> Starlink (Connectivity segment)
B27: Revenue | C27: =IF($I$11=1,0,$C$11) -> 13873 | D27: =IF($I$11=1,IF(D$5>5,(D$5-5)*$D$11/5,0),C27+($H27-C27)*D$6) -> 20948.133 | E27: =IF($I$11=1,IF(E$5>5,(E$5-5)*$D$11/5,0),D27+($H27-D27)*E$6) -> 29438.293 | F27: =IF($I$11=1,IF(F$5>5,(F$5-5)*$D$11/5,0),E27+($H27-E27)*F$6) -> 37362.443 | G27: =IF($I$11=1,IF(G$5>5,(G$5-5)*$D$11/5,0),F27+($H27-F27)*G$6) -> 43305.555 | H27: =IF($I$11=1,IF(H$5>5,(H$5-5)*$D$11/5,0),$C27+($D$11-$C27)/3) -> 49248.667 | I27: =IF($I$11=1,IF(I$5>5,(I$5-5)*$D$11/5,0),H27+($D$11-H27)*I$6) -> 63398.933 | J27: =IF($I$11=1,IF(J$5>5,(J$5-5)*$D$11/5,0),I27+($D$11-I27)*J$6) -> 80379.253 | K27: =IF($I$11=1,IF(K$5>5,(K$5-5)*$D$11/5,0),J27+($D$11-J27)*K$6) -> 96227.552 | L27: =IF($I$11=1,IF(L$5>5,(L$5-5)*$D$11/5,0),K27+($D$11-K27)*L$6) -> 108113.78 | M27: =IF($I$11=1,IF(M$5>5,(M$5-5)*$D$11/5,0),$D$11) -> 120000
B28: Operating margin | C28: =$E$11 -> 0.1 | D28: =IF(D$5>$C$17,$F$11,$F$11-($F$11-$E$11)/$C$17*($C$17-D$5)) -> 0.15 | E28: =IF(E$5>$C$17,$F$11,$F$11-($F$11-$E$11)/$C$17*($C$17-E$5)) -> 0.2 | F28: =IF(F$5>$C$17,$F$11,$F$11-($F$11-$E$11)/$C$17*($C$17-F$5)) -> 0.25 | G28: =IF(G$5>$C$17,$F$11,$F$11-($F$11-$E$11)/$C$17*($C$17-G$5)) -> 0.3 | H28: =IF(H$5>$C$17,$F$11,$F$11-($F$11-$E$11)/$C$17*($C$17-H$5)) -> 0.35 | I28: =IF(I$5>$C$17,$F$11,$F$11-($F$11-$E$11)/$C$17*($C$17-I$5)) -> 0.4 | J28: =IF(J$5>$C$17,$F$11,$F$11-($F$11-$E$11)/$C$17*($C$17-J$5)) -> 0.45 | K28: =IF(K$5>$C$17,$F$11,$F$11-($F$11-$E$11)/$C$17*($C$17-K$5)) -> 0.5 | ... M28: =IF(M$5>$C$17,$F$11,$F$11-($F$11-$E$11)/$C$17*($C$17-M$5)) -> 0.6
B29: Operating income (EBIT) | D29: =D27*D28 -> 3142.22 | E29: =E27*E28 -> 5887.6587 | F29: =F27*F28 -> 9340.6107 | G29: =G27*G28 -> 12991.666 | H29: =H27*H28 -> 17237.033 | I29: =I27*I28 -> 25359.573 | J29: =J27*J28 -> 36170.664 | K29: =K27*K28 -> 48113.776 | ... M29: =M27*M28 -> 72000
B30: Reinvestment | D30: =(D27-C27)/IF(D$5<=5,$G$11,$H$11) -> 2358.3778 | E30: =(E27-D27)/IF(E$5<=5,$G$11,$H$11) -> 2830.0533 | F30: =(F27-E27)/IF(F$5<=5,$G$11,$H$11) -> 2641.3831 | G30: =(G27-F27)/IF(G$5<=5,$G$11,$H$11) -> 1981.0373 | H30: =(H27-G27)/IF(H$5<=5,$G$11,$H$11) -> 1981.0373 | I30: =(I27-H27)/IF(I$5<=5,$G$11,$H$11) -> 2830.0533 | J30: =(J27-I27)/IF(J$5<=5,$G$11,$H$11) -> 3396.064 | K30: =(K27-J27)/IF(K$5<=5,$G$11,$H$11) -> 3169.6597 | ... M30: =(M27-L27)/IF(M$5<=5,$G$11,$H$11) -> 2377.2448
B32: =B12 -> xAI (AI segment)
B33: Revenue | C33: =IF($I$12=1,0,$C$12) -> 5115 | D33: =IF($I$12=1,IF(D$5>5,(D$5-5)*$D$12/5,0),C33+($H33-C33)*D$6) -> 15440.667 | E33: =IF($I$12=1,IF(E$5>5,(E$5-5)*$D$12/5,0),D33+($H33-D33)*E$6) -> 27831.467 | F33: =IF($I$12=1,IF(F$5>5,(F$5-5)*$D$12/5,0),E33+($H33-E33)*F$6) -> 39396.213 | G33: =IF($I$12=1,IF(G$5>5,(G$5-5)*$D$12/5,0),F33+($H33-F33)*G$6) -> 48069.773 | H33: =IF($I$12=1,IF(H$5>5,(H$5-5)*$D$12/5,0),$C33+($D$12-$C33)/3) -> 56743.333 | I33: =IF($I$12=1,IF(I$5>5,(I$5-5)*$D$12/5,0),H33+($D$12-H33)*I$6) -> 77394.667 | J33: =IF($I$12=1,IF(J$5>5,(J$5-5)*$D$12/5,0),I33+($D$12-I33)*J$6) -> 102176.27 | K33: =IF($I$12=1,IF(K$5>5,(K$5-5)*$D$12/5,0),J33+($D$12-J33)*K$6) -> 125305.76 | L33: =IF($I$12=1,IF(L$5>5,(L$5-5)*$D$12/5,0),K33+($D$12-K33)*L$6) -> 142652.88 | M33: =IF($I$12=1,IF(M$5>5,(M$5-5)*$D$12/5,0),$D$12) -> 160000
B34: Operating margin | C34: =$E$12 -> -0.05 | D34: =IF(D$5>$C$17,$F$12,$F$12-($F$12-$E$12)/$C$17*($C$17-D$5)) -> -0.02 | E34: =IF(E$5>$C$17,$F$12,$F$12-($F$12-$E$12)/$C$17*($C$17-E$5)) -> 0.01 | F34: =IF(F$5>$C$17,$F$12,$F$12-($F$12-$E$12)/$C$17*($C$17-F$5)) -> 0.04 | G34: =IF(G$5>$C$17,$F$12,$F$12-($F$12-$E$12)/$C$17*($C$17-G$5)) -> 0.07 | H34: =IF(H$5>$C$17,$F$12,$F$12-($F$12-$E$12)/$C$17*($C$17-H$5)) -> 0.1 | I34: =IF(I$5>$C$17,$F$12,$F$12-($F$12-$E$12)/$C$17*($C$17-I$5)) -> 0.13 | J34: =IF(J$5>$C$17,$F$12,$F$12-($F$12-$E$12)/$C$17*($C$17-J$5)) -> 0.16 | K34: =IF(K$5>$C$17,$F$12,$F$12-($F$12-$E$12)/$C$17*($C$17-K$5)) -> 0.19 | ... M34: =IF(M$5>$C$17,$F$12,$F$12-($F$12-$E$12)/$C$17*($C$17-M$5)) -> 0.25
B35: Operating income (EBIT) | D35: =D33*D34 -> -308.81333 | E35: =E33*E34 -> 278.31467 | F35: =F33*F34 -> 1575.8485 | G35: =G33*G34 -> 3364.8841 | H35: =H33*H34 -> 5674.3333 | I35: =I33*I34 -> 10061.307 | J35: =J33*J34 -> 16348.203 | K35: =K33*K34 -> 23808.094 | ... M35: =M33*M34 -> 40000
B36: Reinvestment | D36: =(D33-C33)/IF(D$5<=5,$G$12,$H$12) -> 6883.7778 | E36: =(E33-D33)/IF(E$5<=5,$G$12,$H$12) -> 8260.5333 | F36: =(F33-E33)/IF(F$5<=5,$G$12,$H$12) -> 7709.8311 | G36: =(G33-F33)/IF(G$5<=5,$G$12,$H$12) -> 5782.3733 | H36: =(H33-G33)/IF(H$5<=5,$G$12,$H$12) -> 5782.3733 | I36: =(I33-H33)/IF(I$5<=5,$G$12,$H$12) -> 8260.5333 | J36: =(J33-I33)/IF(J$5<=5,$G$12,$H$12) -> 9912.64 | K36: =(K33-J33)/IF(K$5<=5,$G$12,$H$12) -> 9251.7973 | ... M36: =(M33-L33)/IF(M$5<=5,$G$12,$H$12) -> 6938.848
B38: =B13 -> Other (expansion options)
B39: Revenue | C39: =IF($I$13=1,0,$C$13) -> 0 | D39: =IF($I$13=1,IF(D$5>5,(D$5-5)*$D$13/5,0),C39+($H39-C39)*D$6) -> 0 | E39: =IF($I$13=1,IF(E$5>5,(E$5-5)*$D$13/5,0),D39+($H39-D39)*E$6) -> 0 | F39: =IF($I$13=1,IF(F$5>5,(F$5-5)*$D$13/5,0),E39+($H39-E39)*F$6) -> 0 | G39: =IF($I$13=1,IF(G$5>5,(G$5-5)*$D$13/5,0),F39+($H39-F39)*G$6) -> 0 | H39: =IF($I$13=1,IF(H$5>5,(H$5-5)*$D$13/5,0),$C39+($D$13-$C39)/3) -> 0 | I39: =IF($I$13=1,IF(I$5>5,(I$5-5)*$D$13/5,0),H39+($D$13-H39)*I$6) -> 20000 | J39: =IF($I$13=1,IF(J$5>5,(J$5-5)*$D$13/5,0),I39+($D$13-I39)*J$6) -> 40000 | K39: =IF($I$13=1,IF(K$5>5,(K$5-5)*$D$13/5,0),J39+($D$13-J39)*K$6) -> 60000 | L39: =IF($I$13=1,IF(L$5>5,(L$5-5)*$D$13/5,0),K39+($D$13-K39)*L$6) -> 80000 | M39: =IF($I$13=1,IF(M$5>5,(M$5-5)*$D$13/5,0),$D$13) -> 100000
B40: Operating margin | C40: =$E$13 -> 0 | D40: =IF(D$5>$C$17,$F$13,$F$13-($F$13-$E$13)/$C$17*($C$17-D$5)) -> 0.03 | E40: =IF(E$5>$C$17,$F$13,$F$13-($F$13-$E$13)/$C$17*($C$17-E$5)) -> 0.06 | F40: =IF(F$5>$C$17,$F$13,$F$13-($F$13-$E$13)/$C$17*($C$17-F$5)) -> 0.09 | G40: =IF(G$5>$C$17,$F$13,$F$13-($F$13-$E$13)/$C$17*($C$17-G$5)) -> 0.12 | H40: =IF(H$5>$C$17,$F$13,$F$13-($F$13-$E$13)/$C$17*($C$17-H$5)) -> 0.15 | I40: =IF(I$5>$C$17,$F$13,$F$13-($F$13-$E$13)/$C$17*($C$17-I$5)) -> 0.18 | J40: =IF(J$5>$C$17,$F$13,$F$13-($F$13-$E$13)/$C$17*($C$17-J$5)) -> 0.21 | K40: =IF(K$5>$C$17,$F$13,$F$13-($F$13-$E$13)/$C$17*($C$17-K$5)) -> 0.24 | ... M40: =IF(M$5>$C$17,$F$13,$F$13-($F$13-$E$13)/$C$17*($C$17-M$5)) -> 0.3
B41: Operating income (EBIT) | D41: =D39*D40 -> 0 | E41: =E39*E40 -> 0 | F41: =F39*F40 -> 0 | G41: =G39*G40 -> 0 | H41: =H39*H40 -> 0 | I41: =I39*I40 -> 3600 | J41: =J39*J40 -> 8400 | K41: =K39*K40 -> 14400 | ... M41: =M39*M40 -> 30000
B42: Reinvestment | D42: =(D39-C39)/IF(D$5<=5,$G$13,$H$13) -> 0 | E42: =(E39-D39)/IF(E$5<=5,$G$13,$H$13) -> 0 | F42: =(F39-E39)/IF(F$5<=5,$G$13,$H$13) -> 0 | G42: =(G39-F39)/IF(G$5<=5,$G$13,$H$13) -> 0 | H42: =(H39-G39)/IF(H$5<=5,$G$13,$H$13) -> 0 | I42: =(I39-H39)/IF(I$5<=5,$G$13,$H$13) -> 4000 | J42: =(J39-I39)/IF(J$5<=5,$G$13,$H$13) -> 4000 | K42: =(K39-J39)/IF(K$5<=5,$G$13,$H$13) -> 4000 | ... M42: =(M39-L39)/IF(M$5<=5,$G$13,$H$13) -> 4000
B44: Total company
B45: Total revenue | C45: =C21+C27+C33+C39 -> 23044 | D45: =D21+D27+D33+D39 -> 42841.067 | E45: =E21+E27+E33+E39 -> 66597.547 | F45: =F21+F27+F33+F39 -> 88770.261 | G45: =G21+G27+G33+G39 -> 105399.8 | H45: =H21+H27+H33+H39 -> 122029.33 | I45: =I21+I27+I33+I39 -> 181623.47 | J45: =J21+J27+J33+J39 -> 249136.43 | ... M45: =M21+M27+M33+M39 -> 420000
B46: Total operating income (EBIT) | D46: =D23+D29+D35+D41 -> 3588.3219 | E46: =E23+E29+E35+E41 -> 7602.4525 | F46: =F23+F29+F35+F41 -> 13210.676 | G46: =G23+G29+G35+G41 -> 19554.13 | H46: =H23+H29+H35+H41 -> 27161.26 | I46: =I23+I29+I35+I41 -> 45311.5 | J46: =J23+J29+J35+J41 -> 69929.794 | K46: =K23+K29+K35+K41 -> 98334.523 | ... M46: =M23+M29+M35+M41 -> 160000
B47: Operating margin | D47: =D46/D45 -> 0.083758929 | E47: =E46/E45 -> 0.11415514 | F47: =F46/F45 -> 0.14881871 | G47: =G46/G45 -> 0.18552341 | H47: =H46/H45 -> 0.22257976 | I47: =I46/I45 -> 0.24948043 | J47: =J46/J45 -> 0.28068876 | K47: =K46/K45 -> 0.31368489 | ... M47: =M46/M45 -> 0.38095238
B48: Total reinvestment | D48: =D24+D30+D36+D42 -> 10040.911 | E48: =E24+E30+E36+E42 -> 12049.093 | F48: =F24+F30+F36+F42 -> 11245.82 | G48: =G24+G30+G36+G42 -> 8434.3653 | H48: =H24+H30+H36+H42 -> 8434.3653 | I48: =I24+I30+I36+I42 -> 16288.72 | J48: =J24+J30+J36+J42 -> 18746.464 | K48: =K24+K30+K36+K42 -> 17763.366 | ... M48: =M24+M30+M36+M42 -> 14322.525

Sheet DCF
B2: Discounted Cash Flow (FCFF)
B3: Damodaran fcffsimpleginzu mechanics: tax drifts to marginal in years 6-10, NOL shield, cost of capital drifts to terminal, terminal reinvestment = g / ROIC. $ in millions except per share.
C4: Base (TTM) | D4: Year 1 | E4: Year 2 | F4: Year 3 | G4: Year 4 | H4: Year 5 | I4: Year 6 | J4: Year 7 | K4: Year 8 | L4: Year 9 | M4: Year 10 | N4: Terminal
B5: Year (t) | C5: 0 | D5: 1 | E5: 2 | F5: 3 | G5: 4 | H5: 5 | I5: 6 | J5: 7 | K5: 8 | L5: 9 | M5: 10
B7: Revenue | C7: =Segments!C45 -> 23044 | D7: =Segments!D45 -> 42841.067 | E7: =Segments!E45 -> 66597.547 | F7: =Segments!F45 -> 88770.261 | G7: =Segments!G45 -> 105399.8 | H7: =Segments!H45 -> 122029.33 | I7: =Segments!I45 -> 181623.47 | J7: =Segments!J45 -> 249136.43 | ... M7: =Segments!M45 -> 420000 | N7: =M7*(1+$C$31) -> 441714
B8: Revenue growth | D8: =D7/C7-1 -> 0.85909854 | E8: =E7/D7-1 -> 0.55452588 | F8: =F7/E7-1 -> 0.33293591 | G8: =G7/F7-1 -> 0.18733229 | H8: =H7/G7-1 -> 0.15777579 | I8: =I7/H7-1 -> 0.48835908 | J8: =J7/I7-1 -> 0.37171937 | K8: =K7/J7-1 -> 0.25827387 | ... N8: =N7/M7-1 -> 0.0517
B9: Operating margin | C9: =C10/C7 -> 0.27877973 | D9: =D10/D7 -> 0.083758929 | E9: =E10/E7 -> 0.11415514 | F9: =F10/F7 -> 0.14881871 | G9: =G10/G7 -> 0.18552341 | H9: =H10/H7 -> 0.22257976 | I9: =I10/I7 -> 0.24948043 | J9: =J10/J7 -> 0.28068876 | ... M9: =M10/M7 -> 0.38095238 | N9: =M9 -> 0.38095238
B10: Operating income (EBIT) | C10: =Inputs!$C$21+C57 -> 6424.2 | D10: =Segments!D46 -> 3588.3219 | E10: =Segments!E46 -> 7602.4525 | F10: =Segments!F46 -> 13210.676 | G10: =Segments!G46 -> 19554.13 | H10: =Segments!H46 -> 27161.26 | I10: =Segments!I46 -> 45311.5 | J10: =Segments!J46 -> 69929.794 | K10: =Segments!K46 -> 98334.523 | ... M10: =Segments!M46 -> 160000 | N10: =N9*N7 -> 168272
B11: Tax rate | C11: =Inputs!$C$37 -> 0.1 | D11: =C11 -> 0.1 | E11: =D11 -> 0.1 | F11: =E11 -> 0.1 | G11: =F11 -> 0.1 | H11: =G11 -> 0.1 | I11: =H11+(Inputs!$C$38-Inputs!$C$37)/5 -> 0.13 | J11: =I11+(Inputs!$C$38-Inputs!$C$37)/5 -> 0.16 | K11: =J11+(Inputs!$C$38-Inputs!$C$37)/5 -> 0.19 | L11: =K11+(Inputs!$C$38-Inputs!$C$37)/5 -> 0.22 | M11: =L11+(Inputs!$C$38-Inputs!$C$37)/5 -> 0.25 | N11: =Inputs!$C$38 -> 0.25
B12: Net operating loss (NOL) | C12: =Inputs!$C$24 -> 0 | D12: =IF(D10<0,C12-D10,IF(C12>D10,C12-D10,0)) -> 0 | E12: =IF(E10<0,D12-E10,IF(D12>E10,D12-E10,0)) -> 0 | F12: =IF(F10<0,E12-F10,IF(E12>F10,E12-F10,0)) -> 0 | G12: =IF(G10<0,F12-G10,IF(F12>G10,F12-G10,0)) -> 0 | H12: =IF(H10<0,G12-H10,IF(G12>H10,G12-H10,0)) -> 0 | I12: =IF(I10<0,H12-I10,IF(H12>I10,H12-I10,0)) -> 0 | J12: =IF(J10<0,I12-J10,IF(I12>J10,I12-J10,0)) -> 0 | K12: =IF(K10<0,J12-K10,IF(J12>K10,J12-K10,0)) -> 0 | ... M12: =IF(M10<0,L12-M10,IF(L12>M10,L12-M10,0)) -> 0
B13: After-tax operating income | C13: =IF(C10>0,C10*(1-C11),C10) -> 5781.78 | D13: =IF(D10>0,IF(D10<C12,D10,D10-(D10-C12)*D11),D10) -> 3229.4897 | E13: =IF(E10>0,IF(E10<D12,E10,E10-(E10-D12)*E11),E10) -> 6842.2072 | F13: =IF(F10>0,IF(F10<E12,F10,F10-(F10-E12)*F11),F10) -> 11889.608 | G13: =IF(G10>0,IF(G10<F12,G10,G10-(G10-F12)*G11),G10) -> 17598.717 | H13: =IF(H10>0,IF(H10<G12,H10,H10-(H10-G12)*H11),H10) -> 24445.134 | I13: =IF(I10>0,IF(I10<H12,I10,I10-(I10-H12)*I11),I10) -> 39421.005 | J13: =IF(J10>0,IF(J10<I12,J10,J10-(J10-I12)*J11),J10) -> 58741.027 | K13: =IF(K10>0,IF(K10<J12,K10,K10-(K10-J12)*K11),K10) -> 79650.964 | ... M13: =IF(M10>0,IF(M10<L12,M10,M10-(M10-L12)*M11),M10) -> 120000 | N13: =N10*(1-N11) -> 126204
B14: Less: reinvestment | D14: =Segments!D48 -> 10040.911 | E14: =Segments!E48 -> 12049.093 | F14: =Segments!F48 -> 11245.82 | G14: =Segments!G48 -> 8434.3653 | H14: =Segments!H48 -> 8434.3653 | I14: =Segments!I48 -> 16288.72 | J14: =Segments!J48 -> 18746.464 | K14: =Segments!K48 -> 17763.366 | ... M14: =Segments!M48 -> 14322.525 | N14: =IF($C$31>0,$C$31/$C$32*N13,0) -> 43498.312
B15: Free cash flow to firm (FCFF) | D15: =D13-D14 -> -6811.4214 | E15: =E13-E14 -> -5206.8861 | F15: =F13-F14 -> 643.78779 | G15: =G13-G14 -> 9164.3513 | H15: =H13-H14 -> 16010.769 | I15: =I13-I14 -> 23132.285 | J15: =J13-J14 -> 39994.563 | K15: =K13-K14 -> 61887.597 | ... N15: =N13-N14 -> 82705.688
B17: Cost of capital | D17: =$C$27 -> 0.10416279 | E17: =$C$27 -> 0.10416279 | F17: =$C$27 -> 0.10416279 | G17: =$C$27 -> 0.10416279 | H17: =$C$27 -> 0.10416279 | I17: =H17-($H$17-$N$17)/5 -> 0.10105023 | J17: =I17-($H$17-$N$17)/5 -> 0.097937674 | K17: =J17-($H$17-$N$17)/5 -> 0.094825116 | L17: =K17-($H$17-$N$17)/5 -> 0.091712558 | M17: =L17-($H$17-$N$17)/5 -> 0.0886 | N17: =$C$28 -> 0.0886
B18: Cumulative discount factor | D18: =1/(1+D17) -> 0.90566356 | E18: =D18/(1+E17) -> 0.82022648 | F18: =E18/(1+F17) -> 0.74284923 | G18: =F18/(1+G17) -> 0.67277148 | H18: =G18/(1+H17) -> 0.60930461 | I18: =H18/(1+I17) -> 0.55338493 | J18: =I18/(1+J17) -> 0.50402217 | K18: =J18/(1+K17) -> 0.46036775 | L18: =K18/(1+L17) -> 0.42169319 | M18: =L18/(1+M17) -> 0.38737203
B19: Present value of FCFF | D19: =D15*D18 -> -6168.8562 | E19: =E15*E18 -> -4270.8259 | F19: =F15*F18 -> 478.23727 | G19: =G15*G18 -> 6165.5141 | H19: =H15*H18 -> 9755.4351 | I19: =I15*I18 -> 12801.058 | J19: =J15*J18 -> 20158.147 | K19: =K15*K18 -> 28491.054 | ... M19: =M15*M18 -> 40936.498
B21: Invested capital | C21: =Inputs!$C$17+Inputs!$C$16-Inputs!$C$15+C55 -> 83843.2 | D21: =C21+D14 -> 93884.111 | E21: =D21+E14 -> 105933.2 | F21: =E21+F14 -> 117179.02 | G21: =F21+G14 -> 125613.39 | H21: =G21+H14 -> 134047.76 | I21: =H21+I14 -> 150336.48 | J21: =I21+J14 -> 169082.94 | K21: =J21+K14 -> 186846.31 | ... M21: =L21+M14 -> 215491.36
B22: Return on invested capital | C22: =C13/C21 -> 0.068959439 | D22: =D13/C21 -> 0.038518206 | E22: =E13/D21 -> 0.072879289 | F22: =F13/E21 -> 0.11223684 | G22: =G13/F21 -> 0.15018658 | H22: =H13/G21 -> 0.19460612 | I22: =I13/H21 -> 0.2940818 | J22: =J13/I21 -> 0.39073037 | K22: =K13/J21 -> 0.47107629 | ... M22: =M13/L21 -> 0.59651388 | N22: =$C$32 -> 0.15
B25: Valuation
B26: Cost of capital (from WACC tab) | C26: =WACC_Initial -> 0.10416279
B27: Initial cost of capital (incl. flex) | C27: =C26+Sensitivity!$C$5 -> 0.10416279
B28: Terminal cost of capital (live) | C28: =Scenarios!$E$22+Sensitivity!$C$6+Sensitivity!$C$9 -> 0.0886
B29: Riskfree rate (live) | C29: =WACC!C20 -> 0.0517
B30: Stable growth rule | C30: ="Terminal growth = riskfree rate (Ginzu default)" -> Terminal growth = riskfree rate (Ginzu default)
B31: Terminal growth rate | C31: =C29 -> 0.0517
B32: Terminal return on capital | C32: =Inputs!$C$42 -> 0.15
B33: Terminal value = FCFF(t+1) / (r - g) | C33: =N15/(C28-C31) -> 2241346.6
B34: PV of terminal value | C34: =C33*M18 -> 868234.96
B35: PV of FCFF, years 1-10 | C35: =SUM(D19:M19) -> 144179.33
B36: Sum of present values | C36: =C34+C35 -> 1012414.3
B37: Probability of failure | C37: =Inputs!$C$43 -> 0
B38: Proceeds if the firm fails | C38: =C36*Inputs!$C$44 -> 506207.14
B39: Value of operating assets | C39: =C36*(1-C37)+C38*C37 -> 1012414.3
B40: Less: debt | C40: =Inputs!$C$16 -> 39364
B41: Less: minority interests | C41: =Inputs!$C$18 -> 0
B42: Plus: cash & marketable securities | C42: =Inputs!$C$15 -> 100009
B43: Plus: non-operating assets | C43: =Inputs!$C$19 -> 0
B44: Plus: IPO proceeds not yet received | C44: =Inputs!$C$20 -> 0
B45: Value of equity | C45: =C39-C40-C41+C42+C43+C44 -> 1073059.3
B46: Less: value of employee options | C46: =Inputs!$C$25 -> 0
...

Sheet Diagnostics
B2: Diagnostics
B3: The Ginzu 'Diagnostics' sheet: the forecast set against industry averages, with the questions Damodaran suggests asking
B5: 1. Revenue growth
C6: Industry (5-yr avg) | D6: Last year | E6: Next year | F6: CAGR yrs 2-5 | H6: Growth above industry: is the company small? Very different from last year's growth: why?
C7: =Inputs!$C$72 -> 0.110999 | D7: =DCF!C7/Inputs!$C$23-1 -> 0.23401521 | E7: =DCF!D8 -> 0.85909854 | F7: =(DCF!H7/DCF!D7)^(1/4)-1 -> 0.29912515
B9: 2. Dollar revenues
C10: Now (TTM) | D10: Year 1 | E10: Year 5 | F10: Year 10 | H10: How big is the total market; what do its biggest firms earn; what share does year 10 imply? (Damodaran rejected the prospectus $28trn TAM as fantasy.)
C11: =DCF!C7 -> 23044 | D11: =DCF!D7 -> 42841.067 | E11: =DCF!H7 -> 122029.33 | F11: =DCF!M7 -> 420000
B13: 3. Operating margin
C14: Industry | D14: Now (R&D adj.) | E14: Year 5 | F14: Year 10 | H14: Industry margins? Unit economics (the cost of the extra unit)? What does competition look like?
C15: =Inputs!$C$73 -> 0.087654 | D15: =DCF!C9 -> 0.27877973 | E15: =DCF!H9 -> 0.22257976 | F15: =DCF!M9 -> 0.38095238
B17: 4. Reinvestment & ROIC
C18: Industry sales/capital | D18: Sales/capital now | E18: ROIC year 10 | F18: Stable ROIC | H18: Bounce-back or new growth? Excess capacity? Does efficiency change with scale? H1-2026 capex was $28.5bn vs ~$10bn year-1 reinvestment here.
C19: =Inputs!$C$74 -> 2.74341 | D19: =DCF!C7/DCF!C21 -> 0.27484638 | E19: =DCF!M22 -> 0.59651388 | F19: =DCF!N22 -> 0.15
B21: 5. Cost of capital
C22: Industry | D22: Years 1-5 | E22: Compounded | F22: Stable | H22: How does it compare with the industry? What happens to it over time, and why?
C23: =Inputs!$C$75 -> 0.076015 | D23: =DCF!D17 -> 0.10416279 | E23: =(1/DCF!M18)^(1/10)-1 -> 0.099479597 | F23: =DCF!N17 -> 0.0886
B25: 6. Value vs price
C26: Value / price | D26: Flag | H26: Ginzu flags: value below 50% or above 200% of price -> revisit growth, target margin, sales/capital and terminal ROIC.
C27: =DCF!C49/DCF!C50 -> 0.54751637 | D27: =IF(DCF!C49/DCF!C50<0.5,"Value low: revisit",IF(DCF!C49/DCF!C50>2,"Value high: revisit","Within 0.5x-2x")) -> Within 0.5x-2x

Sheet Checks
B2: Model Checks
B3: Ties the workbook to the aswath-finance engine (calibrated to Damodaran's spreadsheets) and to the Ginzu rules. Engine reference values are hard-coded outputs of spacex_model.py on 2026-09-25.
B5: # | C5: Check | D5: Workbook | E5: Engine / rule | F5: Result | G5: Note
B6: 1 | C6: Model in base state (scenario 1, flex cells neutral) | D6: =IF(AND(Scenarios!$D$5=1,Sensitivity!$C$5=0,Sensitivity!$C$6=0,Sensitivity!$C$7=1,Sensitivity!$C$8=0,Sensitivity!$C$9=0),"Base","Flexed") -> Base | E6: ="Base" -> Base | F6: =AND(Scenarios!$D$5=1,Sensitivity!$C$5=0,Sensitivity!$C$6=0,Sensitivity!$C$7=1,Sensitivity!$C$8=0,Sensitivity!$C$9=0) -> TRUE | G6: Tie-outs below are only meaningful in base state
B7: 2 | C7: Value per share ties to engine | D7: =ValuePerShare -> 81.404733 | E7: 81.404733 | F7: =IF(AND(Scenarios!$D$5=1,Sensitivity!$C$5=0,Sensitivity!$C$6=0,Sensitivity!$C$7=1,Sensitivity!$C$8=0,Sensitivity!$C$9=0),ABS(D7-E7)<0.005,TRUE) -> TRUE | G7: spacex_model.py sep_2026_inputs.json
B8: 3 | C8: Initial cost of capital ties to engine | D8: =WACC_Initial -> 0.10416279 | E8: 0.10416279 | F8: =IF(AND(Scenarios!$D$5=1,Sensitivity!$C$5=0,Sensitivity!$C$6=0,Sensitivity!$C$7=1,Sensitivity!$C$8=0,Sensitivity!$C$9=0),ABS(D8-E8)<0.000001,TRUE) -> TRUE | G8: cost_of_capital.py (Damodaran's method)
B9: 4 | C9: Scenario values tie to engine (max abs difference, $) | D9: =MAX(ABS(Scenarios!K8-81.4047334998042),ABS(Scenarios!K9-88.9136073497478),ABS(Scenarios!K10-89.5855876628464),ABS(Scenarios!K11-95.8888391206215),ABS(Scenarios!K12-72.5180122798146),ABS(Scenarios!K13-73.1403616659594),ABS(Scenarios!K14-89.6691053336489),ABS(Scenarios!K15-75.1352786215379),ABS(Scenarios!K16-87.6741883780705),ABS(Scenarios!K17-77.4370478757327),ABS(Scenarios!K18-62.577650815443),ABS(Scenarios!K19-100.231816184165)) -> 2.0168756e-09 | E9: 0 | F9: =D9<0.01 -> TRUE | G9: spacex_model.py --sensitivity, 12 scenarios
B10: 5 | C10: Year-10 revenue = sum of live 2036 targets | D10: =DCF!M7 -> 420000 | E10: =SUM(Segments!D10:D13) -> 420000 | F10: =ABS(D10-E10)<0.001 -> TRUE | G10: Segment path lands on the 2036 targets
B11: 6 | C11: Terminal growth <= riskfree (Ginzu rule) | D11: =DCF!C31 -> 0.0517 | E11: =DCF!C29 -> 0.0517 | F11: =D11<=E11+0.0000001 -> TRUE | G11: Stable growth capped at riskfree
B12: 7 | C12: Terminal ROIC >= terminal cost of capital (Ginzu rule) | D12: =DCF!C32 -> 0.15 | E12: =DCF!C28 -> 0.0886 | F12: =D12>=E12 -> TRUE | G12: Otherwise growth destroys value
B13: 8 | C13: Sensitivity table 1 centre = base value | D13: =Sensitivity!E18 -> 81.404733 | E13: =ValuePerShare -> 81.404733 | F13: =IF(AND(Scenarios!$D$5=1,Sensitivity!$C$5=0,Sensitivity!$C$6=0,Sensitivity!$C$7=1,Sensitivity!$C$8=0,Sensitivity!$C$9=0),ABS(D13-E13)<0.005,TRUE) -> TRUE | G13: Data table recalculated by Excel
B14: 9 | C14: Sensitivity table 2 (1.00x, 0%) = base value | D14: =Sensitivity!E29 -> 81.404733 | E14: =ValuePerShare -> 81.404733 | F14: =IF(AND(Scenarios!$D$5=1,Sensitivity!$C$5=0,Sensitivity!$C$6=0,Sensitivity!$C$7=1,Sensitivity!$C$8=0,Sensitivity!$C$9=0),ABS(D14-E14)<0.005,TRUE) -> TRUE
B15: 10 | C15: Equity bridge adds up | D15: =DCF!C45 -> 1073059.3 | E15: =DCF!C39-DCF!C40-DCF!C41+DCF!C42+DCF!C43+DCF!C44 -> 1073059.3 | F15: =ABS(D15-E15)<0.001 -> TRUE
B16: 11 | C16: Value walk ends at the engine value | D16: =Summary!C43 -> 81.4047 | E16: 81.404733 | F16: =ABS(D16-E16)<0.005 -> TRUE | G16: Engine attribution
B17: 12 | C17: Breakeven multiplier reproduces the price | D17: =Sensitivity!E33 -> 148.65507 | E17: =SharePrice -> 148.68 | F17: =IF(AND(Scenarios!$D$5=1,Sensitivity!$C$5=0,Sensitivity!$C$6=0,Sensitivity!$C$7=1,Sensitivity!$C$8=0,Sensitivity!$C$9=0),ABS(D17-E17)<0.05,TRUE) -> TRUE | G17: Row 1.89x, 0% margin change
C19: ALL CHECKS PASS | F19: =COUNTIF(F6:F17,FALSE)=0 -> TRUE

Sheet Sources
B2: Sources, Methodology & Notes
B3: Every input traces to a filing, market data, or Damodaran's own model/data
B5: Sources and notes
C6: Filings | D6: SpaceX Q2-2026 Form 10-Q: https://www.sec.gov/Archives/edgar/data/0001181412/000162828026052535/spcx-20260630.htm
D7: SpaceX Q2-2026 earnings release: https://www.sec.gov/Archives/edgar/data/1181412/000162828026052515/earningsreleaseq22608042.htm
C8: Market data | D8: StockAnalysis SPCX (close, 52-week range, analyst target), 25-Sep-2026: https://stockanalysis.com/stocks/spcx/
D9: US 10-year Treasury 5.17%, 25-Sep-2026: https://www.cnbc.com/2026/09/25/treasury-yields-bonds-debt.html
D10: Q2-2026 results context (AI capex): https://www.cnbc.com/2026/08/04/spacex-spcx-earnings-live-updates-q2-2026.html
C11: Damodaran model | D11: Damodaran, SpaceX2026IPOUpdated.xlsx (June 2026): https://pages.stern.nyu.edu/~adamodar/pc/blog/SpaceX2026IPOUpdated.xlsx
C12: Damodaran posts | D12: Revisiting the SpaceX Valuation (2026-06): https://aswathdamodaran.blogspot.com/2026/06/a-weeks-ago-i-assessed-value-of-spacex.html
D13: To a Trillion(s) Dollars and beyond: A SpaceX IPO Odyssey (2026-04): https://aswathdamodaran.blogspot.com/2026/04/to-trillion-dollars-and-beyond-spacex.html
C14: Damodaran data | D14: fcffsimpleginzu.xlsx industry averages & rating spreads (Jan-2026); ctrypremJuly26.xlsx country ERPs (Jul-2026): pages.stern.nyu.edu/~adamodar
C15: Methodology | D15: FCFF DCF transcribed from Damodaran's fcffsimpleginzu spreadsheet; the aswath-finance engine reproduces 31 published Damodaran valuations exactly.
D16: Segment mechanics transcribed from Damodaran's June 2026 SpaceX workbook (rebuilt from raw inputs to its $97.8277/share).
D17: Cost of capital: Damodaran's worksheet method (multi-business beta, operating-country ERP, rating spread), reproduced exactly at 8.3745% for June.
C18: Judgment calls | D18: 1) Beta weights updated from the stale April mix to TTM segment revenues (the literal June weights: see Scenario 2).
D19: 2) Terminal cost of capital = the June model's 8.25% moved with the riskfree rate (+0.61pt), following Damodaran's riskfree-adjustment convention.
D20: 3) Base segment margins, operating-country weights, Ba2/BB rating and excluded options kept from the June model (not disclosed in the 10-Q).
D21: 4) Share count from the 10-Q cover (13,182m); StockAnalysis shows 13.57bn, which would lower value/share by about 2.9%.
D22: 5) The story (2036 revenue targets, target margins, sales-to-capital) is Damodaran's June 2026 story, unchanged.
C23: Damodaran's stance (June 2026) | D23: At the $135 offer price: "too richly priced for my tastes"; "as an investor, I would not sell short, notwithstanding my value assessment".
C24: Disclaimer | D24: Educational application of Damodaran's public framework and data. Not investment advice, not a recommendation, and not affiliated with or endorsed by Damodaran or any bank.
